{
  "version": 8,
  "blockIdVersion": 11,
  "anchorX": 0,
  "anchorY": 0,
  "anchorZ": 0,
  "blocks": [
    {
      "x": 1,
      "y": 1,
      "z": -9,
      "name": "Rock_Stone_Cobble"
    },
    {
      "x": 1,
      "y": 9,
      "z": -9,
      "name": "Wood_Softwood_Roof_Hollow",
      "rotation": 3
    },
    {
      "x": 1,
      "y": 1,
      "z": -8,
      "name": "Rock_Stone_Cobble"
    },
    {
      "x": 1,
      "y": 8,
      "z": -8,
      "name": "Wood_Beech_Branch_Corner",
      "support": 15,
      "rotation": 3
    },
    {
      "x": 1,
      "y": 9,
      "z": -8,
      "name": "Wood_Softwood_Roof",
      "rotation": 3
    },
    {
      "x": 1,
      "y": 1,
      "z": -7,
      "name": "Rock_Stone_Cobble"
    },
    {
      "x": 1,
      "y": 5,
      "z": -7,
      "name": "Plant_Vine_Wall",
      "support": 15,
      "rotation": 3
    },
    {
      "x": 1,
      "y": 9,
      "z": -7,
      "name": "Wood_Softwood_Roof_Hollow",
      "rotation": 3
    },
    {
      "x": 1,
      "y": 1,
      "z": -6,
      "name": "Rock_Stone_Cobble"
    },
    {
      "x": 1,
      "y": 9,
      "z": -6,
      "name": "Wood_Softwood_Roof_Hollow",
      "rotation": 3
    },
    {
      "x": 1,
      "y": 1,
      "z": -5,
      "name": "Rock_Stone_Cobble"
    },
    {
      "x": 1,
      "y": 6,
      "z": -5,
      "name": "Plant_Vine_Wall",
      "support": 15,
      "rotation": 3
    },
    {
      "x": 1,
      "y": 9,
      "z": -5,
      "name": "Wood_Softwood_Roof_Hollow",
      "rotation": 3
    },
    {
      "x": 1,
      "y": 1,
      "z": -4,
      "name": "Rock_Stone_Cobble"
    },
    {
      "x": 1,
      "y": 9,
      "z": -4,
      "name": "Wood_Softwood_Roof_Hollow",
      "rotation": 3
    },
    {
      "x": 1,
      "y": 1,
      "z": -3,
      "name": "Rock_Stone_Cobble_Mossy"
    },
    {
      "x": 1,
      "y": 4,
      "z": -3,
      "name": "Plant_Vine_Wall",
      "support": 15,
      "rotation": 3
    },
    {
      "x": 1,
      "y": 9,
      "z": -3,
      "name": "Wood_Softwood_Roof_Hollow",
      "rotation": 3
    },
    {
      "x": 1,
      "y": 1,
      "z": -2,
      "name": "Rock_Stone_Cobble"
    },
    {
      "x": 1,
      "y": 8,
      "z": -2,
      "name": "Wood_Beech_Branch_Corner",
      "support": 15,
      "rotation": 3
    },
    {
      "x": 1,
      "y": 9,
      "z": -2,
      "name": "Wood_Softwood_Roof",
      "rotation": 3
    },
    {
      "x": 1,
      "y": 1,
      "z": -1,
      "name": "Rock_Stone_Cobble"
    },
    {
      "x": 1,
      "y": 9,
      "z": -1,
      "name": "Wood_Softwood_Roof_Hollow",
      "rotation": 3
    },
    {
      "x": 2,
      "y": 1,
      "z": -9,
      "name": "Rock_Stone_Cobble"
    },
    {
      "x": 2,
      "y": 9,
      "z": -9,
      "name": "Wood_Beech_Branch_Corner",
      "support": 15,
      "rotation": 2
    },
    {
      "x": 2,
      "y": 10,
      "z": -9,
      "name": "Wood_Softwood_Roof",
      "rotation": 3
    },
    {
      "x": 2,
      "y": 1,
      "z": -8,
      "name": "Rock_Stone_Cobble_Mossy"
    },
    {
      "x": 2,
      "y": 2,
      "z": -8,
      "name": "Wood_Beech_Trunk",
      "support": 15
    },
    {
      "x": 2,
      "y": 3,
      "z": -8,
      "name": "Wood_Beech_Trunk",
      "support": 15
    },
    {
      "x": 2,
      "y": 4,
      "z": -8,
      "name": "Wood_Beech_Trunk",
      "support": 15
    },
    {
      "x": 2,
      "y": 5,
      "z": -8,
      "name": "Wood_Beech_Trunk",
      "support": 15
    },
    {
      "x": 2,
      "y": 6,
      "z": -8,
      "name": "Wood_Beech_Trunk",
      "support": 15
    },
    {
      "x": 2,
      "y": 7,
      "z": -8,
      "name": "Wood_Beech_Trunk",
      "support": 15
    },
    {
      "x": 2,
      "y": 8,
      "z": -8,
      "name": "Wood_Beech_Trunk",
      "support": 15
    },
    {
      "x": 2,
      "y": 9,
      "z": -8,
      "name": "Wood_Beech_Trunk",
      "support": 15
    },
    {
      "x": 2,
      "y": 10,
      "z": -8,
      "name": "Wood_Softwood_Roof",
      "rotation": 3
    },
    {
      "x": 2,
      "y": 1,
      "z": -7,
      "name": "Rock_Stone_Cobble"
    },
    {
      "x": 2,
      "y": 2,
      "z": -7,
      "name": "Rock_Stone_Brick_Mossy"
    },
    {
      "x": 2,
      "y": 3,
      "z": -7,
      "name": "*Wood_Village_Wall_Full_State_Definitions_Bottom"
    },
    {
      "x": 2,
      "y": 4,
      "z": -7,
      "name": "*Wood_Village_Wall_Full_State_Definitions_Top"
    },
    {
      "x": 2,
      "y": 5,
      "z": -7,
      "name": "Wood_Beech_Trunk",
      "support": 15,
      "rotation": 4
    },
    {
      "x": 2,
      "y": 6,
      "z": -7,
      "name": "*Wood_Village_Wall_Full_State_Definitions_Bottom"
    },
    {
      "x": 2,
      "y": 7,
      "z": -7,
      "name": "*Wood_Village_Wall_Full_State_Definitions_Middle"
    },
    {
      "x": 2,
      "y": 8,
      "z": -7,
      "name": "*Wood_Village_Wall_Full_State_Definitions_Top"
    },
    {
      "x": 2,
      "y": 9,
      "z": -7,
      "name": "Wood_Beech_Trunk",
      "support": 15,
      "rotation": 4
    },
    {
      "x": 2,
      "y": 10,
      "z": -7,
      "name": "Wood_Softwood_Roof",
      "rotation": 3
    },
    {
      "x": 2,
      "y": 1,
      "z": -6,
      "name": "Rock_Stone_Cobble"
    },
    {
      "x": 2,
      "y": 2,
      "z": -6,
      "name": "Rock_Stone_Brick"
    },
    {
      "x": 2,
      "y": 3,
      "z": -6,
      "name": "Furniture_Village_Window",
      "rotation": 1
    },
    {
      "x": 2,
      "y": 4,
      "z": -6,
      "name": "Furniture_Village_Window",
      "rotation": 1
    },
    {
      "x": 2,
      "y": 5,
      "z": -6,
      "name": "Wood_Beech_Trunk",
      "support": 15,
      "rotation": 4
    },
    {
      "x": 2,
      "y": 6,
      "z": -6,
      "name": "Wood_Village_Wall_Full"
    },
    {
      "x": 2,
      "y": 7,
      "z": -6,
      "name": "Furniture_Village_Window",
      "rotation": 1
    },
    {
      "x": 2,
      "y": 8,
      "z": -6,
      "name": "Wood_Village_Wall_Full"
    },
    {
      "x": 2,
      "y": 9,
      "z": -6,
      "name": "Wood_Beech_Trunk",
      "support": 15,
      "rotation": 4
    },
    {
      "x": 2,
      "y": 10,
      "z": -6,
      "name": "Wood_Softwood_Roof",
      "rotation": 3
    },
    {
      "x": 2,
      "y": 1,
      "z": -5,
      "name": "Rock_Stone_Cobble"
    },
    {
      "x": 2,
      "y": 2,
      "z": -5,
      "name": "Rock_Stone_Brick"
    },
    {
      "x": 2,
      "y": 3,
      "z": -5,
      "name": "*Wood_Village_Wall_Full_State_Definitions_Bottom"
    },
    {
      "x": 2,
      "y": 4,
      "z": -5,
      "name": "*Wood_Village_Wall_Full_State_Definitions_Top"
    },
    {
      "x": 2,
      "y": 5,
      "z": -5,
      "name": "Wood_Beech_Trunk",
      "support": 15,
      "rotation": 4
    },
    {
      "x": 2,
      "y": 6,
      "z": -5,
      "name": "*Wood_Village_Wall_Full_State_Definitions_Bottom"
    },
    {
      "x": 2,
      "y": 7,
      "z": -5,
      "name": "*Wood_Village_Wall_Full_State_Definitions_Middle"
    },
    {
      "x": 2,
      "y": 8,
      "z": -5,
      "name": "*Wood_Village_Wall_Full_State_Definitions_Top"
    },
    {
      "x": 2,
      "y": 9,
      "z": -5,
      "name": "Wood_Beech_Trunk",
      "support": 15,
      "rotation": 4
    },
    {
      "x": 2,
      "y": 10,
      "z": -5,
      "name": "Wood_Softwood_Roof",
      "rotation": 3
    },
    {
      "x": 2,
      "y": 1,
      "z": -4,
      "name": "Rock_Stone_Cobble"
    },
    {
      "x": 2,
      "y": 2,
      "z": -4,
      "name": "Rock_Stone_Brick"
    },
    {
      "x": 2,
      "y": 3,
      "z": -4,
      "name": "Furniture_Village_Window",
      "rotation": 1
    },
    {
      "x": 2,
      "y": 4,
      "z": -4,
      "name": "Furniture_Village_Window",
      "rotation": 1
    },
    {
      "x": 2,
      "y": 5,
      "z": -4,
      "name": "Wood_Beech_Trunk",
      "support": 15,
      "rotation": 4
    },
    {
      "x": 2,
      "y": 6,
      "z": -4,
      "name": "Wood_Village_Wall_Full"
    },
    {
      "x": 2,
      "y": 7,
      "z": -4,
      "name": "Furniture_Village_Window",
      "rotation": 1
    },
    {
      "x": 2,
      "y": 8,
      "z": -4,
      "name": "Wood_Village_Wall_Full"
    },
    {
      "x": 2,
      "y": 9,
      "z": -4,
      "name": "Wood_Beech_Trunk",
      "support": 15,
      "rotation": 4
    },
    {
      "x": 2,
      "y": 10,
      "z": -4,
      "name": "Wood_Softwood_Roof",
      "rotation": 3
    },
    {
      "x": 2,
      "y": 1,
      "z": -3,
      "name": "Rock_Stone_Cobble"
    },
    {
      "x": 2,
      "y": 2,
      "z": -3,
      "name": "Rock_Stone_Brick_Mossy"
    },
    {
      "x": 2,
      "y": 3,
      "z": -3,
      "name": "*Wood_Village_Wall_Full_State_Definitions_Bottom"
    },
    {
      "x": 2,
      "y": 4,
      "z": -3,
      "name": "*Wood_Village_Wall_Full_State_Definitions_Top"
    },
    {
      "x": 2,
      "y": 5,
      "z": -3,
      "name": "Wood_Beech_Trunk",
      "support": 15,
      "rotation": 4
    },
    {
      "x": 2,
      "y": 6,
      "z": -3,
      "name": "*Wood_Village_Wall_Full_State_Definitions_Bottom"
    },
    {
      "x": 2,
      "y": 7,
      "z": -3,
      "name": "*Wood_Village_Wall_Full_State_Definitions_Middle"
    },
    {
      "x": 2,
      "y": 8,
      "z": -3,
      "name": "*Wood_Village_Wall_Full_State_Definitions_Top"
    },
    {
      "x": 2,
      "y": 9,
      "z": -3,
      "name": "Wood_Beech_Trunk",
      "support": 15,
      "rotation": 4
    },
    {
      "x": 2,
      "y": 10,
      "z": -3,
      "name": "Wood_Softwood_Roof",
      "rotation": 3
    },
    {
      "x": 2,
      "y": 1,
      "z": -2,
      "name": "Rock_Stone_Cobble"
    },
    {
      "x": 2,
      "y": 2,
      "z": -2,
      "name": "Wood_Beech_Trunk",
      "support": 15
    },
    {
      "x": 2,
      "y": 3,
      "z": -2,
      "name": "Wood_Beech_Trunk",
      "support": 15
    },
    {
      "x": 2,
      "y": 4,
      "z": -2,
      "name": "Wood_Beech_Trunk",
      "support": 15
    },
    {
      "x": 2,
      "y": 5,
      "z": -2,
      "name": "Wood_Beech_Trunk",
      "support": 15
    },
    {
      "x": 2,
      "y": 6,
      "z": -2,
      "name": "Wood_Beech_Trunk",
      "support": 15
    },
    {
      "x": 2,
      "y": 7,
      "z": -2,
      "name": "Wood_Beech_Trunk",
      "support": 15
    },
    {
      "x": 2,
      "y": 8,
      "z": -2,
      "name": "Wood_Beech_Trunk",
      "support": 15
    },
    {
      "x": 2,
      "y": 9,
      "z": -2,
      "name": "Wood_Beech_Trunk",
      "support": 15
    },
    {
      "x": 2,
      "y": 10,
      "z": -2,
      "name": "Wood_Softwood_Roof",
      "rotation": 3
    },
    {
      "x": 2,
      "y": 1,
      "z": -1,
      "name": "Rock_Stone_Cobble"
    },
    {
      "x": 2,
      "y": 9,
      "z": -1,
      "name": "Wood_Beech_Branch_Corner",
      "support": 15
    },
    {
      "x": 2,
      "y": 10,
      "z": -1,
      "name": "Wood_Softwood_Roof",
      "rotation": 3
    },
    {
      "x": 3,
      "y": 1,
      "z": -9,
      "name": "Rock_Stone_Cobble"
    },
    {
      "x": 3,
      "y": 8,
      "z": -9,
      "name": "Plant_Vine_Wall",
      "support": 15,
      "rotation": 2
    },
    {
      "x": 3,
      "y": 10,
      "z": -9,
      "name": "Wood_Softwood_Stairs",
      "rotation": 11
    },
    {
      "x": 3,
      "y": 11,
      "z": -9,
      "name": "Wood_Softwood_Roof",
      "rotation": 3
    },
    {
      "x": 3,
      "y": 1,
      "z": -8,
      "name": "Rock_Stone_Cobble"
    },
    {
      "x": 3,
      "y": 2,
      "z": -8,
      "name": "Rock_Stone_Brick"
    },
    {
      "x": 3,
      "y": 3,
      "z": -8,
      "name": "*Wood_Village_Wall_Full_State_Definitions_Bottom"
    },
    {
      "x": 3,
      "y": 4,
      "z": -8,
      "name": "*Wood_Village_Wall_Full_State_Definitions_Top"
    },
    {
      "x": 3,
      "y": 5,
      "z": -8,
      "name": "Wood_Beech_Trunk",
      "support": 15,
      "rotation": 5
    },
    {
      "x": 3,
      "y": 6,
      "z": -8,
      "name": "*Wood_Village_Wall_Full_State_Definitions_Bottom"
    },
    {
      "x": 3,
      "y": 7,
      "z": -8,
      "name": "*Wood_Village_Wall_Full_State_Definitions_Middle"
    },
    {
      "x": 3,
      "y": 8,
      "z": -8,
      "name": "*Wood_Village_Wall_Full_State_Definitions_Top"
    },
    {
      "x": 3,
      "y": 9,
      "z": -8,
      "name": "Wood_Beech_Trunk",
      "support": 15,
      "rotation": 5
    },
    {
      "x": 3,
      "y": 10,
      "z": -8,
      "name": "Wood_Village_Wall_Full"
    },
    {
      "x": 3,
      "y": 11,
      "z": -8,
      "name": "Wood_Softwood_Roof",
      "rotation": 3
    },
    {
      "x": 3,
      "y": 1,
      "z": -7,
      "name": "Wood_Softwood_Planks"
    },
    {
      "x": 3,
      "y": 10,
      "z": -7,
      "name": "Wood_Softwood_Stairs",
      "rotation": 11
    },
    {
      "x": 3,
      "y": 11,
      "z": -7,
      "name": "Wood_Softwood_Roof",
      "rotation": 3
    },
    {
      "x": 3,
      "y": 1,
      "z": -6,
      "name": "Wood_Softwood_Planks"
    },
    {
      "x": 3,
      "y": 5,
      "z": -6,
      "name": "Wood_Softwood_Planks"
    },
    {
      "x": 3,
      "y": 10,
      "z": -6,
      "name": "Wood_Softwood_Stairs",
      "rotation": 11
    },
    {
      "x": 3,
      "y": 11,
      "z": -6,
      "name": "Wood_Softwood_Roof",
      "rotation": 3
    },
    {
      "x": 3,
      "y": 1,
      "z": -5,
      "name": "Wood_Softwood_Planks"
    },
    {
      "x": 3,
      "y": 2,
      "z": -5,
      "name": "Wood_Greenwood_Planks"
    },
    {
      "x": 3,
      "y": 5,
      "z": -5,
      "name": "Wood_Softwood_Planks"
    },
    {
      "x": 3,
      "y": 6,
      "z": -5,
      "name": "Furniture_Village_Chair",
      "rotation": 2
    },
    {
      "x": 3,
      "y": 7,
      "z": -5,
      "name": "Furniture_Village_Chair",
      "filler": 1024,
      "rotation": 2
    },
    {
      "x": 3,
      "y": 10,
      "z": -5,
      "name": "Wood_Softwood_Stairs",
      "rotation": 11
    },
    {
      "x": 3,
      "y": 11,
      "z": -5,
      "name": "Wood_Softwood_Roof",
      "rotation": 3
    },
    {
      "x": 3,
      "y": 1,
      "z": -4,
      "name": "Wood_Softwood_Planks"
    },
    {
      "x": 3,
      "y": 2,
      "z": -4,
      "name": "Aetherhaven_Wood_Scaffold",
      "support": 15,
      "rotation": 1
    },
    {
      "x": 3,
      "y": 5,
      "z": -4,
      "name": "Wood_Softwood_Planks"
    },
    {
      "x": 3,
      "y": 6,
      "z": -4,
      "name": "Rock_Aqua_Brick_Decorative"
    },
    {
      "x": 3,
      "y": 10,
      "z": -4,
      "name": "Wood_Softwood_Stairs",
      "rotation": 11
    },
    {
      "x": 3,
      "y": 11,
      "z": -4,
      "name": "Wood_Softwood_Roof",
      "rotation": 3
    },
    {
      "x": 3,
      "y": 1,
      "z": -3,
      "name": "Wood_Softwood_Planks"
    },
    {
      "x": 3,
      "y": 2,
      "z": -3,
      "name": "Furniture_Tavern_Candle"
    },
    {
      "x": 3,
      "y": 5,
      "z": -3,
      "name": "Wood_Softwood_Planks"
    },
    {
      "x": 3,
      "y": 6,
      "z": -3,
      "name": "Rock_Aqua_Brick"
    },
    {
      "x": 3,
      "y": 7,
      "z": -3,
      "name": "Rock_Chalk_Brick"
    },
    {
      "x": 3,
      "y": 10,
      "z": -3,
      "name": "Wood_Softwood_Stairs",
      "rotation": 11
    },
    {
      "x": 3,
      "y": 11,
      "z": -3,
      "name": "Wood_Softwood_Roof",
      "rotation": 3
    },
    {
      "x": 3,
      "y": 1,
      "z": -2,
      "name": "Rock_Stone_Cobble"
    },
    {
      "x": 3,
      "y": 2,
      "z": -2,
      "name": "Rock_Stone_Brick"
    },
    {
      "x": 3,
      "y": 3,
      "z": -2,
      "name": "*Wood_Village_Wall_Full_State_Definitions_Bottom"
    },
    {
      "x": 3,
      "y": 4,
      "z": -2,
      "name": "*Wood_Village_Wall_Full_State_Definitions_Top"
    },
    {
      "x": 3,
      "y": 5,
      "z": -2,
      "name": "Wood_Beech_Trunk",
      "support": 15,
      "rotation": 5
    },
    {
      "x": 3,
      "y": 6,
      "z": -2,
      "name": "*Wood_Village_Wall_Full_State_Definitions_Bottom"
    },
    {
      "x": 3,
      "y": 7,
      "z": -2,
      "name": "*Wood_Village_Wall_Full_State_Definitions_Middle"
    },
    {
      "x": 3,
      "y": 8,
      "z": -2,
      "name": "*Wood_Village_Wall_Full_State_Definitions_Top"
    },
    {
      "x": 3,
      "y": 9,
      "z": -2,
      "name": "Wood_Beech_Trunk",
      "support": 15,
      "rotation": 5
    },
    {
      "x": 3,
      "y": 10,
      "z": -2,
      "name": "Wood_Village_Wall_Full"
    },
    {
      "x": 3,
      "y": 11,
      "z": -2,
      "name": "Wood_Softwood_Roof",
      "rotation": 3
    },
    {
      "x": 3,
      "y": 1,
      "z": -1,
      "name": "Rock_Stone_Cobble"
    },
    {
      "x": 3,
      "y": 6,
      "z": -1,
      "name": "Plant_Vine_Wall",
      "support": 15
    },
    {
      "x": 3,
      "y": 10,
      "z": -1,
      "name": "Wood_Softwood_Stairs",
      "rotation": 11
    },
    {
      "x": 3,
      "y": 11,
      "z": -1,
      "name": "Wood_Softwood_Roof",
      "rotation": 3
    },
    {
      "x": 4,
      "y": 1,
      "z": -9,
      "name": "Rock_Stone_Cobble_Mossy"
    },
    {
      "x": 4,
      "y": 11,
      "z": -9,
      "name": "Wood_Softwood_Stairs",
      "rotation": 11
    },
    {
      "x": 4,
      "y": 12,
      "z": -9,
      "name": "Wood_Softwood_Roof",
      "rotation": 3
    },
    {
      "x": 4,
      "y": 1,
      "z": -8,
      "name": "Rock_Stone_Cobble"
    },
    {
      "x": 4,
      "y": 2,
      "z": -8,
      "name": "Rock_Stone_Brick_Mossy"
    },
    {
      "x": 4,
      "y": 3,
      "z": -8,
      "name": "*Wood_Village_Wall_Full_State_Definitions_Bottom"
    },
    {
      "x": 4,
      "y": 4,
      "z": -8,
      "name": "*Wood_Village_Wall_Full_State_Definitions_Top"
    },
    {
      "x": 4,
      "y": 5,
      "z": -8,
      "name": "Wood_Beech_Trunk",
      "support": 15,
      "rotation": 5
    },
    {
      "x": 4,
      "y": 6,
      "z": -8,
      "name": "Wood_Village_Wall_Full"
    },
    {
      "x": 4,
      "y": 7,
      "z": -8,
      "name": "Furniture_Village_Window"
    },
    {
      "x": 4,
      "y": 8,
      "z": -8,
      "name": "Wood_Village_Wall_Full"
    },
    {
      "x": 4,
      "y": 9,
      "z": -8,
      "name": "Wood_Beech_Trunk",
      "support": 15,
      "rotation": 5
    },
    {
      "x": 4,
      "y": 10,
      "z": -8,
      "name": "*Wood_Village_Wall_Full_State_Definitions_Bottom"
    },
    {
      "x": 4,
      "y": 11,
      "z": -8,
      "name": "*Wood_Village_Wall_Full_State_Definitions_Top"
    },
    {
      "x": 4,
      "y": 12,
      "z": -8,
      "name": "Wood_Softwood_Roof",
      "rotation": 3
    },
    {
      "x": 4,
      "y": 1,
      "z": -7,
      "name": "Wood_Softwood_Planks"
    },
    {
      "x": 4,
      "y": 2,
      "z": -7,
      "name": "Wood_Softwood_Stairs",
      "rotation": 3
    },
    {
      "x": 4,
      "y": 11,
      "z": -7,
      "name": "Wood_Softwood_Stairs",
      "rotation": 11
    },
    {
      "x": 4,
      "y": 12,
      "z": -7,
      "name": "Wood_Softwood_Roof",
      "rotation": 3
    },
    {
      "x": 4,
      "y": 1,
      "z": -6,
      "name": "Wood_Softwood_Planks"
    },
    {
      "x": 4,
      "y": 5,
      "z": -6,
      "name": "Wood_Softwood_Planks"
    },
    {
      "x": 4,
      "y": 11,
      "z": -6,
      "name": "Wood_Softwood_Stairs",
      "rotation": 11
    },
    {
      "x": 4,
      "y": 12,
      "z": -6,
      "name": "Wood_Softwood_Roof",
      "rotation": 3
    },
    {
      "x": 4,
      "y": 1,
      "z": -5,
      "name": "Wood_Softwood_Planks"
    },
    {
      "x": 4,
      "y": 5,
      "z": -5,
      "name": "Wood_Softwood_Planks"
    },
    {
      "x": 4,
      "y": 11,
      "z": -5,
      "name": "Wood_Softwood_Stairs",
      "rotation": 11
    },
    {
      "x": 4,
      "y": 12,
      "z": -5,
      "name": "Wood_Softwood_Roof",
      "rotation": 3
    },
    {
      "x": 4,
      "y": 1,
      "z": -4,
      "name": "Wood_Softwood_Planks"
    },
    {
      "x": 4,
      "y": 5,
      "z": -4,
      "name": "Wood_Softwood_Planks"
    },
    {
      "x": 4,
      "y": 11,
      "z": -4,
      "name": "Wood_Softwood_Stairs",
      "rotation": 11
    },
    {
      "x": 4,
      "y": 12,
      "z": -4,
      "name": "Wood_Softwood_Roof",
      "rotation": 3
    },
    {
      "x": 4,
      "y": 1,
      "z": -3,
      "name": "Wood_Softwood_Planks"
    },
    {
      "x": 4,
      "y": 5,
      "z": -3,
      "name": "Wood_Softwood_Planks"
    },
    {
      "x": 4,
      "y": 6,
      "z": -3,
      "name": "Furniture_Village_Door",
      "rotation": 2
    },
    {
      "x": 4,
      "y": 7,
      "z": -3,
      "name": "Furniture_Village_Door",
      "filler": 1024,
      "rotation": 2
    },
    {
      "x": 4,
      "y": 11,
      "z": -3,
      "name": "Wood_Softwood_Stairs",
      "rotation": 11
    },
    {
      "x": 4,
      "y": 12,
      "z": -3,
      "name": "Wood_Softwood_Roof",
      "rotation": 3
    },
    {
      "x": 4,
      "y": 1,
      "z": -2,
      "name": "Rock_Stone_Cobble"
    },
    {
      "x": 4,
      "y": 2,
      "z": -2,
      "name": "Rock_Stone_Brick"
    },
    {
      "x": 4,
      "y": 3,
      "z": -2,
      "name": "*Wood_Village_Wall_Full_State_Definitions_Bottom"
    },
    {
      "x": 4,
      "y": 4,
      "z": -2,
      "name": "*Wood_Village_Wall_Full_State_Definitions_Top"
    },
    {
      "x": 4,
      "y": 5,
      "z": -2,
      "name": "Wood_Beech_Trunk",
      "support": 15,
      "rotation": 5
    },
    {
      "x": 4,
      "y": 6,
      "z": -2,
      "name": "Wood_Village_Wall_Full"
    },
    {
      "x": 4,
      "y": 7,
      "z": -2,
      "name": "Furniture_Village_Window"
    },
    {
      "x": 4,
      "y": 8,
      "z": -2,
      "name": "Wood_Village_Wall_Full"
    },
    {
      "x": 4,
      "y": 9,
      "z": -2,
      "name": "Wood_Beech_Trunk",
      "support": 15,
      "rotation": 5
    },
    {
      "x": 4,
      "y": 10,
      "z": -2,
      "name": "*Wood_Village_Wall_Full_State_Definitions_Bottom"
    },
    {
      "x": 4,
      "y": 11,
      "z": -2,
      "name": "*Wood_Village_Wall_Full_State_Definitions_Top"
    },
    {
      "x": 4,
      "y": 12,
      "z": -2,
      "name": "Wood_Softwood_Roof",
      "rotation": 3
    },
    {
      "x": 4,
      "y": 1,
      "z": -1,
      "name": "Rock_Stone_Cobble_Mossy"
    },
    {
      "x": 4,
      "y": 2,
      "z": -1,
      "name": "Wood_Softwood_Beam"
    },
    {
      "x": 4,
      "y": 3,
      "z": -1,
      "name": "Wood_Softwood_Beam"
    },
    {
      "x": 4,
      "y": 4,
      "z": -1,
      "name": "*Wood_Softwood_Roof_State_Definitions_Corner_Left",
      "rotation": 3
    },
    {
      "x": 4,
      "y": 11,
      "z": -1,
      "name": "Wood_Softwood_Stairs",
      "rotation": 11
    },
    {
      "x": 4,
      "y": 12,
      "z": -1,
      "name": "Wood_Softwood_Roof",
      "rotation": 3
    },
    {
      "x": 5,
      "y": 1,
      "z": -9,
      "name": "Rock_Stone_Cobble"
    },
    {
      "x": 5,
      "y": 5,
      "z": -9,
      "name": "Plant_Vine_Wall",
      "support": 15,
      "rotation": 2
    },
    {
      "x": 5,
      "y": 12,
      "z": -9,
      "name": "Wood_Softwood_Planks"
    },
    {
      "x": 5,
      "y": 13,
      "z": -9,
      "name": "Wood_Softwood_Roof_Flat",
      "rotation": 1
    },
    {
      "x": 5,
      "y": 1,
      "z": -8,
      "name": "Rock_Stone_Cobble_Mossy"
    },
    {
      "x": 5,
      "y": 2,
      "z": -8,
      "name": "Rock_Stone_Brick"
    },
    {
      "x": 5,
      "y": 3,
      "z": -8,
      "name": "*Wood_Village_Wall_Full_State_Definitions_Bottom"
    },
    {
      "x": 5,
      "y": 4,
      "z": -8,
      "name": "*Wood_Village_Wall_Full_State_Definitions_Top"
    },
    {
      "x": 5,
      "y": 5,
      "z": -8,
      "name": "Wood_Beech_Trunk",
      "support": 15,
      "rotation": 5
    },
    {
      "x": 5,
      "y": 6,
      "z": -8,
      "name": "*Wood_Village_Wall_Full_State_Definitions_Bottom"
    },
    {
      "x": 5,
      "y": 7,
      "z": -8,
      "name": "*Wood_Village_Wall_Full_State_Definitions_Middle"
    },
    {
      "x": 5,
      "y": 8,
      "z": -8,
      "name": "*Wood_Village_Wall_Full_State_Definitions_Top"
    },
    {
      "x": 5,
      "y": 9,
      "z": -8,
      "name": "Wood_Beech_Trunk",
      "support": 15,
      "rotation": 5
    },
    {
      "x": 5,
      "y": 10,
      "z": -8,
      "name": "Furniture_Village_Window"
    },
    {
      "x": 5,
      "y": 11,
      "z": -8,
      "name": "*Wood_Village_Wall_Full_State_Definitions_Bottom"
    },
    {
      "x": 5,
      "y": 12,
      "z": -8,
      "name": "*Wood_Village_Wall_Full_State_Definitions_Top"
    },
    {
      "x": 5,
      "y": 13,
      "z": -8,
      "name": "Wood_Softwood_Roof_Flat",
      "rotation": 1
    },
    {
      "x": 5,
      "y": 1,
      "z": -7,
      "name": "Wood_Softwood_Planks"
    },
    {
      "x": 5,
      "y": 2,
      "z": -7,
      "name": "Wood_Softwood_Stairs",
      "rotation": 11
    },
    {
      "x": 5,
      "y": 3,
      "z": -7,
      "name": "Wood_Softwood_Stairs",
      "rotation": 3
    },
    {
      "x": 5,
      "y": 12,
      "z": -7,
      "name": "Wood_Softwood_Planks"
    },
    {
      "x": 5,
      "y": 13,
      "z": -7,
      "name": "Wood_Softwood_Roof_Flat",
      "rotation": 1
    },
    {
      "x": 5,
      "y": 1,
      "z": -6,
      "name": "Wood_Softwood_Planks"
    },
    {
      "x": 5,
      "y": 5,
      "z": -6,
      "name": "Wood_Softwood_Planks"
    },
    {
      "x": 5,
      "y": 12,
      "z": -6,
      "name": "Wood_Softwood_Planks"
    },
    {
      "x": 5,
      "y": 13,
      "z": -6,
      "name": "Wood_Softwood_Roof_Flat",
      "rotation": 1
    },
    {
      "x": 5,
      "y": 1,
      "z": -5,
      "name": "Wood_Softwood_Planks"
    },
    {
      "x": 5,
      "y": 5,
      "z": -5,
      "name": "Wood_Softwood_Planks"
    },
    {
      "x": 5,
      "y": 9,
      "z": -5,
      "name": "Deco_Lantern_Ceiling"
    },
    {
      "x": 5,
      "y": 10,
      "z": -5,
      "name": "Deco_Rope"
    },
    {
      "x": 5,
      "y": 11,
      "z": -5,
      "name": "Deco_Rope"
    },
    {
      "x": 5,
      "y": 12,
      "z": -5,
      "name": "Wood_Softwood_Planks"
    },
    {
      "x": 5,
      "y": 13,
      "z": -5,
      "name": "Wood_Softwood_Roof_Flat",
      "rotation": 1
    },
    {
      "x": 5,
      "y": 1,
      "z": -4,
      "name": "Wood_Softwood_Planks"
    },
    {
      "x": 5,
      "y": 5,
      "z": -4,
      "name": "Wood_Softwood_Planks"
    },
    {
      "x": 5,
      "y": 12,
      "z": -4,
      "name": "Wood_Softwood_Planks"
    },
    {
      "x": 5,
      "y": 13,
      "z": -4,
      "name": "Wood_Softwood_Roof_Flat",
      "rotation": 1
    },
    {
      "x": 5,
      "y": 1,
      "z": -3,
      "name": "Wood_Softwood_Planks"
    },
    {
      "x": 5,
      "y": 5,
      "z": -3,
      "name": "Wood_Softwood_Planks"
    },
    {
      "x": 5,
      "y": 6,
      "z": -3,
      "name": "Wood_Drywood_Planks"
    },
    {
      "x": 5,
      "y": 7,
      "z": -3,
      "name": "Wood_Deadwood_Planks"
    },
    {
      "x": 5,
      "y": 12,
      "z": -3,
      "name": "Wood_Softwood_Planks"
    },
    {
      "x": 5,
      "y": 13,
      "z": -3,
      "name": "Wood_Softwood_Roof_Flat",
      "rotation": 1
    },
    {
      "x": 5,
      "y": 1,
      "z": -2,
      "name": "Wood_Softwood_Planks"
    },
    {
      "x": 5,
      "y": 2,
      "z": -2,
      "name": "*Furniture_Village_Door_State_Definitions_CloseDoorOut"
    },
    {
      "x": 5,
      "y": 3,
      "z": -2,
      "name": "*Furniture_Village_Door_State_Definitions_CloseDoorOut",
      "filler": 1024
    },
    {
      "x": 5,
      "y": 4,
      "z": -2,
      "name": "Wood_Village_Wall_Full"
    },
    {
      "x": 5,
      "y": 5,
      "z": -2,
      "name": "Wood_Beech_Trunk",
      "support": 15,
      "rotation": 5
    },
    {
      "x": 5,
      "y": 6,
      "z": -2,
      "name": "*Wood_Village_Wall_Full_State_Definitions_Bottom"
    },
    {
      "x": 5,
      "y": 7,
      "z": -2,
      "name": "*Wood_Village_Wall_Full_State_Definitions_Middle"
    },
    {
      "x": 5,
      "y": 8,
      "z": -2,
      "name": "*Wood_Village_Wall_Full_State_Definitions_Top"
    },
    {
      "x": 5,
      "y": 9,
      "z": -2,
      "name": "Wood_Beech_Trunk",
      "support": 15,
      "rotation": 5
    },
    {
      "x": 5,
      "y": 10,
      "z": -2,
      "name": "Furniture_Village_Window"
    },
    {
      "x": 5,
      "y": 11,
      "z": -2,
      "name": "*Wood_Village_Wall_Full_State_Definitions_Bottom"
    },
    {
      "x": 5,
      "y": 12,
      "z": -2,
      "name": "*Wood_Village_Wall_Full_State_Definitions_Top"
    },
    {
      "x": 5,
      "y": 13,
      "z": -2,
      "name": "Wood_Softwood_Roof_Flat",
      "rotation": 3
    },
    {
      "x": 5,
      "y": 1,
      "z": -1,
      "name": "Rock_Stone_Cobble"
    },
    {
      "x": 5,
      "y": 4,
      "z": -1,
      "name": "Wood_Softwood_Roof_Hollow"
    },
    {
      "x": 5,
      "y": 5,
      "z": -1,
      "name": "Furniture_Village_Sign",
      "rotation": 1
    },
    {
      "x": 5,
      "y": 12,
      "z": -1,
      "name": "Wood_Softwood_Planks"
    },
    {
      "x": 5,
      "y": 13,
      "z": -1,
      "name": "Wood_Softwood_Roof_Flat",
      "rotation": 3
    },
    {
      "x": 6,
      "y": 1,
      "z": -9,
      "name": "Rock_Stone_Cobble"
    },
    {
      "x": 6,
      "y": 11,
      "z": -9,
      "name": "Wood_Softwood_Stairs",
      "rotation": 9
    },
    {
      "x": 6,
      "y": 12,
      "z": -9,
      "name": "Wood_Softwood_Roof",
      "rotation": 1
    },
    {
      "x": 6,
      "y": 1,
      "z": -8,
      "name": "Rock_Stone_Cobble_Mossy"
    },
    {
      "x": 6,
      "y": 2,
      "z": -8,
      "name": "Rock_Stone_Brick"
    },
    {
      "x": 6,
      "y": 3,
      "z": -8,
      "name": "*Wood_Village_Wall_Full_State_Definitions_Bottom"
    },
    {
      "x": 6,
      "y": 4,
      "z": -8,
      "name": "*Wood_Village_Wall_Full_State_Definitions_Top"
    },
    {
      "x": 6,
      "y": 5,
      "z": -8,
      "name": "Wood_Beech_Trunk",
      "support": 15,
      "rotation": 5
    },
    {
      "x": 6,
      "y": 6,
      "z": -8,
      "name": "Wood_Village_Wall_Full"
    },
    {
      "x": 6,
      "y": 7,
      "z": -8,
      "name": "Furniture_Village_Window"
    },
    {
      "x": 6,
      "y": 8,
      "z": -8,
      "name": "Wood_Village_Wall_Full"
    },
    {
      "x": 6,
      "y": 9,
      "z": -8,
      "name": "Wood_Beech_Trunk",
      "support": 15,
      "rotation": 5
    },
    {
      "x": 6,
      "y": 10,
      "z": -8,
      "name": "*Wood_Village_Wall_Full_State_Definitions_Bottom"
    },
    {
      "x": 6,
      "y": 11,
      "z": -8,
      "name": "*Wood_Village_Wall_Full_State_Definitions_Top"
    },
    {
      "x": 6,
      "y": 12,
      "z": -8,
      "name": "Wood_Softwood_Roof",
      "rotation": 1
    },
    {
      "x": 6,
      "y": 1,
      "z": -7,
      "name": "Wood_Softwood_Planks"
    },
    {
      "x": 6,
      "y": 2,
      "z": -7,
      "name": "Aetherhaven_Management_Block",
      "components": {
        "Components": {
          "AetherhavenManagementBlock": {
            "PlotId": "",
            "TownId": ""
          },
          "PlacedByInteraction": {
            "WhoPlacedUuid": {
              "$binary": "v7RyWIT/TYKnXA2XcxdQtw==",
              "$type": "04"
            }
          }
        }
      }
    },
    {
      "x": 6,
      "y": 3,
      "z": -7,
      "name": "Wood_Softwood_Stairs",
      "rotation": 11
    },
    {
      "x": 6,
      "y": 4,
      "z": -7,
      "name": "Wood_Softwood_Stairs",
      "rotation": 3
    },
    {
      "x": 6,
      "y": 11,
      "z": -7,
      "name": "Wood_Softwood_Stairs",
      "rotation": 9
    },
    {
      "x": 6,
      "y": 12,
      "z": -7,
      "name": "Wood_Softwood_Roof",
      "rotation": 1
    },
    {
      "x": 6,
      "y": 1,
      "z": -6,
      "name": "Wood_Softwood_Planks"
    },
    {
      "x": 6,
      "y": 5,
      "z": -6,
      "name": "Wood_Softwood_Planks"
    },
    {
      "x": 6,
      "y": 11,
      "z": -6,
      "name": "Wood_Softwood_Stairs",
      "rotation": 9
    },
    {
      "x": 6,
      "y": 12,
      "z": -6,
      "name": "Wood_Softwood_Roof",
      "rotation": 1
    },
    {
      "x": 6,
      "y": 1,
      "z": -5,
      "name": "Wood_Softwood_Planks"
    },
    {
      "x": 6,
      "y": 5,
      "z": -5,
      "name": "Wood_Softwood_Planks"
    },
    {
      "x": 6,
      "y": 11,
      "z": -5,
      "name": "Wood_Softwood_Stairs",
      "rotation": 9
    },
    {
      "x": 6,
      "y": 12,
      "z": -5,
      "name": "Wood_Softwood_Roof",
      "rotation": 1
    },
    {
      "x": 6,
      "y": 1,
      "z": -4,
      "name": "Wood_Softwood_Planks"
    },
    {
      "x": 6,
      "y": 5,
      "z": -4,
      "name": "Wood_Softwood_Planks"
    },
    {
      "x": 6,
      "y": 11,
      "z": -4,
      "name": "Wood_Softwood_Stairs",
      "rotation": 9
    },
    {
      "x": 6,
      "y": 12,
      "z": -4,
      "name": "Wood_Softwood_Roof",
      "rotation": 1
    },
    {
      "x": 6,
      "y": 1,
      "z": -3,
      "name": "Wood_Softwood_Planks"
    },
    {
      "x": 6,
      "y": 5,
      "z": -3,
      "name": "Wood_Softwood_Planks"
    },
    {
      "x": 6,
      "y": 6,
      "z": -3,
      "name": "Wood_Goldenwood_Ornate"
    },
    {
      "x": 6,
      "y": 11,
      "z": -3,
      "name": "Wood_Softwood_Stairs",
      "rotation": 9
    },
    {
      "x": 6,
      "y": 12,
      "z": -3,
      "name": "Wood_Softwood_Roof",
      "rotation": 1
    },
    {
      "x": 6,
      "y": 1,
      "z": -2,
      "name": "Rock_Stone_Cobble_Mossy"
    },
    {
      "x": 6,
      "y": 2,
      "z": -2,
      "name": "Rock_Stone_Brick"
    },
    {
      "x": 6,
      "y": 3,
      "z": -2,
      "name": "*Wood_Village_Wall_Full_State_Definitions_Bottom"
    },
    {
      "x": 6,
      "y": 4,
      "z": -2,
      "name": "*Wood_Village_Wall_Full_State_Definitions_Top"
    },
    {
      "x": 6,
      "y": 5,
      "z": -2,
      "name": "Wood_Beech_Trunk",
      "support": 15,
      "rotation": 5
    },
    {
      "x": 6,
      "y": 6,
      "z": -2,
      "name": "Wood_Village_Wall_Full"
    },
    {
      "x": 6,
      "y": 7,
      "z": -2,
      "name": "Furniture_Village_Window"
    },
    {
      "x": 6,
      "y": 8,
      "z": -2,
      "name": "Wood_Village_Wall_Full"
    },
    {
      "x": 6,
      "y": 9,
      "z": -2,
      "name": "Wood_Beech_Trunk",
      "support": 15,
      "rotation": 5
    },
    {
      "x": 6,
      "y": 10,
      "z": -2,
      "name": "*Wood_Village_Wall_Full_State_Definitions_Bottom"
    },
    {
      "x": 6,
      "y": 11,
      "z": -2,
      "name": "*Wood_Village_Wall_Full_State_Definitions_Top"
    },
    {
      "x": 6,
      "y": 12,
      "z": -2,
      "name": "Wood_Softwood_Roof",
      "rotation": 1
    },
    {
      "x": 6,
      "y": 1,
      "z": -1,
      "name": "Rock_Stone_Cobble"
    },
    {
      "x": 6,
      "y": 2,
      "z": -1,
      "name": "Wood_Softwood_Beam"
    },
    {
      "x": 6,
      "y": 3,
      "z": -1,
      "name": "Wood_Softwood_Beam"
    },
    {
      "x": 6,
      "y": 4,
      "z": -1,
      "name": "*Wood_Softwood_Roof_State_Definitions_Corner_Right",
      "rotation": 1
    },
    {
      "x": 6,
      "y": 11,
      "z": -1,
      "name": "Wood_Softwood_Stairs",
      "rotation": 9
    },
    {
      "x": 6,
      "y": 12,
      "z": -1,
      "name": "Wood_Softwood_Roof",
      "rotation": 1
    },
    {
      "x": 7,
      "y": 1,
      "z": -9,
      "name": "Rock_Stone_Cobble"
    },
    {
      "x": 7,
      "y": 10,
      "z": -9,
      "name": "Wood_Softwood_Stairs",
      "rotation": 9
    },
    {
      "x": 7,
      "y": 11,
      "z": -9,
      "name": "Wood_Softwood_Roof",
      "rotation": 1
    },
    {
      "x": 7,
      "y": 1,
      "z": -8,
      "name": "Rock_Stone_Cobble"
    },
    {
      "x": 7,
      "y": 2,
      "z": -8,
      "name": "Rock_Stone_Brick"
    },
    {
      "x": 7,
      "y": 3,
      "z": -8,
      "name": "*Wood_Village_Wall_Full_State_Definitions_Bottom"
    },
    {
      "x": 7,
      "y": 4,
      "z": -8,
      "name": "*Wood_Village_Wall_Full_State_Definitions_Top"
    },
    {
      "x": 7,
      "y": 5,
      "z": -8,
      "name": "Wood_Beech_Trunk",
      "support": 15,
      "rotation": 5
    },
    {
      "x": 7,
      "y": 6,
      "z": -8,
      "name": "*Wood_Village_Wall_Full_State_Definitions_Bottom"
    },
    {
      "x": 7,
      "y": 7,
      "z": -8,
      "name": "*Wood_Village_Wall_Full_State_Definitions_Middle"
    },
    {
      "x": 7,
      "y": 8,
      "z": -8,
      "name": "*Wood_Village_Wall_Full_State_Definitions_Top"
    },
    {
      "x": 7,
      "y": 9,
      "z": -8,
      "name": "Wood_Beech_Trunk",
      "support": 15,
      "rotation": 5
    },
    {
      "x": 7,
      "y": 10,
      "z": -8,
      "name": "Wood_Village_Wall_Full"
    },
    {
      "x": 7,
      "y": 11,
      "z": -8,
      "name": "Wood_Softwood_Roof",
      "rotation": 1
    },
    {
      "x": 7,
      "y": 1,
      "z": -7,
      "name": "Wood_Softwood_Planks"
    },
    {
      "x": 7,
      "y": 2,
      "z": -7,
      "name": "Furniture_Temple_Dark_Candle"
    },
    {
      "x": 7,
      "y": 3,
      "z": -7,
      "name": "Furniture_Temple_Dark_Candle",
      "filler": 1024
    },
    {
      "x": 7,
      "y": 4,
      "z": -7,
      "name": "Wood_Softwood_Stairs",
      "rotation": 11
    },
    {
      "x": 7,
      "y": 5,
      "z": -7,
      "name": "Wood_Softwood_Stairs",
      "rotation": 3
    },
    {
      "x": 7,
      "y": 10,
      "z": -7,
      "name": "Wood_Softwood_Stairs",
      "rotation": 9
    },
    {
      "x": 7,
      "y": 11,
      "z": -7,
      "name": "Wood_Softwood_Roof",
      "rotation": 1
    },
    {
      "x": 7,
      "y": 1,
      "z": -6,
      "name": "Wood_Softwood_Planks"
    },
    {
      "x": 7,
      "y": 2,
      "z": -6,
      "name": "Bench_Builders",
      "filler": 992,
      "rotation": 3
    },
    {
      "x": 7,
      "y": 3,
      "z": -6,
      "name": "Bench_Builders",
      "filler": 2016,
      "rotation": 3
    },
    {
      "x": 7,
      "y": 5,
      "z": -6,
      "name": "Wood_Softwood_Planks"
    },
    {
      "x": 7,
      "y": 10,
      "z": -6,
      "name": "Wood_Softwood_Stairs",
      "rotation": 9
    },
    {
      "x": 7,
      "y": 11,
      "z": -6,
      "name": "Wood_Softwood_Roof",
      "rotation": 1
    },
    {
      "x": 7,
      "y": 1,
      "z": -5,
      "name": "Wood_Softwood_Planks"
    },
    {
      "x": 7,
      "y": 2,
      "z": -5,
      "name": "Bench_Builders",
      "components": {
        "Components": {
          "PlacedByInteraction": {
            "WhoPlacedUuid": {
              "$binary": "v7RyWIT/TYKnXA2XcxdQtw==",
              "$type": "04"
            }
          },
          "BenchBlock": {
            "TierLevel": 1,
            "UpgradeItems": []
          }
        }
      },
      "rotation": 3
    },
    {
      "x": 7,
      "y": 3,
      "z": -5,
      "name": "Bench_Builders",
      "filler": 1024,
      "rotation": 3
    },
    {
      "x": 7,
      "y": 5,
      "z": -5,
      "name": "Wood_Softwood_Planks"
    },
    {
      "x": 7,
      "y": 10,
      "z": -5,
      "name": "Wood_Softwood_Stairs",
      "rotation": 9
    },
    {
      "x": 7,
      "y": 11,
      "z": -5,
      "name": "Wood_Softwood_Roof",
      "rotation": 1
    },
    {
      "x": 7,
      "y": 1,
      "z": -4,
      "name": "Wood_Softwood_Planks"
    },
    {
      "x": 7,
      "y": 2,
      "z": -4,
      "name": "Rock_Basalt_Brick"
    },
    {
      "x": 7,
      "y": 5,
      "z": -4,
      "name": "Wood_Softwood_Planks"
    },
    {
      "x": 7,
      "y": 6,
      "z": -4,
      "name": "Rock_Lime_Brick"
    },
    {
      "x": 7,
      "y": 10,
      "z": -4,
      "name": "Wood_Softwood_Stairs",
      "rotation": 9
    },
    {
      "x": 7,
      "y": 11,
      "z": -4,
      "name": "Wood_Softwood_Roof",
      "rotation": 1
    },
    {
      "x": 7,
      "y": 1,
      "z": -3,
      "name": "Wood_Softwood_Planks"
    },
    {
      "x": 7,
      "y": 2,
      "z": -3,
      "name": "Rock_Basalt_Brick"
    },
    {
      "x": 7,
      "y": 3,
      "z": -3,
      "name": "Rock_Basalt_Brick_Ornate"
    },
    {
      "x": 7,
      "y": 5,
      "z": -3,
      "name": "Wood_Softwood_Planks"
    },
    {
      "x": 7,
      "y": 6,
      "z": -3,
      "name": "Rock_Ledge_Brick"
    },
    {
      "x": 7,
      "y": 7,
      "z": -3,
      "name": "Furniture_Village_Chair",
      "rotation": 3
    },
    {
      "x": 7,
      "y": 8,
      "z": -3,
      "name": "Furniture_Village_Chair",
      "filler": 1024,
      "rotation": 3
    },
    {
      "x": 7,
      "y": 10,
      "z": -3,
      "name": "Wood_Softwood_Stairs",
      "rotation": 9
    },
    {
      "x": 7,
      "y": 11,
      "z": -3,
      "name": "Wood_Softwood_Roof",
      "rotation": 1
    },
    {
      "x": 7,
      "y": 1,
      "z": -2,
      "name": "Rock_Stone_Cobble_Mossy"
    },
    {
      "x": 7,
      "y": 2,
      "z": -2,
      "name": "Rock_Stone_Brick_Mossy"
    },
    {
      "x": 7,
      "y": 3,
      "z": -2,
      "name": "*Wood_Village_Wall_Full_State_Definitions_Bottom"
    },
    {
      "x": 7,
      "y": 4,
      "z": -2,
      "name": "*Wood_Village_Wall_Full_State_Definitions_Top"
    },
    {
      "x": 7,
      "y": 5,
      "z": -2,
      "name": "Wood_Beech_Trunk",
      "support": 15,
      "rotation": 5
    },
    {
      "x": 7,
      "y": 6,
      "z": -2,
      "name": "*Wood_Village_Wall_Full_State_Definitions_Bottom"
    },
    {
      "x": 7,
      "y": 7,
      "z": -2,
      "name": "*Wood_Village_Wall_Full_State_Definitions_Middle"
    },
    {
      "x": 7,
      "y": 8,
      "z": -2,
      "name": "*Wood_Village_Wall_Full_State_Definitions_Top"
    },
    {
      "x": 7,
      "y": 9,
      "z": -2,
      "name": "Wood_Beech_Trunk",
      "support": 15,
      "rotation": 5
    },
    {
      "x": 7,
      "y": 10,
      "z": -2,
      "name": "Wood_Village_Wall_Full"
    },
    {
      "x": 7,
      "y": 11,
      "z": -2,
      "name": "Wood_Softwood_Roof",
      "rotation": 1
    },
    {
      "x": 7,
      "y": 1,
      "z": -1,
      "name": "Rock_Stone_Cobble"
    },
    {
      "x": 7,
      "y": 9,
      "z": -1,
      "name": "Plant_Vine_Wall",
      "support": 15
    },
    {
      "x": 7,
      "y": 10,
      "z": -1,
      "name": "Wood_Softwood_Stairs",
      "rotation": 9
    },
    {
      "x": 7,
      "y": 11,
      "z": -1,
      "name": "Wood_Softwood_Roof",
      "rotation": 1
    },
    {
      "x": 8,
      "y": 1,
      "z": -9,
      "name": "Rock_Stone_Cobble"
    },
    {
      "x": 8,
      "y": 7,
      "z": -9,
      "name": "Plant_Vine_Wall",
      "support": 15,
      "rotation": 2
    },
    {
      "x": 8,
      "y": 9,
      "z": -9,
      "name": "Wood_Beech_Branch_Corner",
      "support": 15,
      "rotation": 2
    },
    {
      "x": 8,
      "y": 10,
      "z": -9,
      "name": "Wood_Softwood_Roof",
      "rotation": 1
    },
    {
      "x": 8,
      "y": 1,
      "z": -8,
      "name": "Rock_Stone_Cobble"
    },
    {
      "x": 8,
      "y": 2,
      "z": -8,
      "name": "Wood_Beech_Trunk",
      "support": 15
    },
    {
      "x": 8,
      "y": 3,
      "z": -8,
      "name": "Wood_Beech_Trunk",
      "support": 15
    },
    {
      "x": 8,
      "y": 4,
      "z": -8,
      "name": "Wood_Beech_Trunk",
      "support": 15
    },
    {
      "x": 8,
      "y": 5,
      "z": -8,
      "name": "Wood_Beech_Trunk",
      "support": 15
    },
    {
      "x": 8,
      "y": 6,
      "z": -8,
      "name": "Wood_Beech_Trunk",
      "support": 15
    },
    {
      "x": 8,
      "y": 7,
      "z": -8,
      "name": "Wood_Beech_Trunk",
      "support": 15
    },
    {
      "x": 8,
      "y": 8,
      "z": -8,
      "name": "Wood_Beech_Trunk",
      "support": 15
    },
    {
      "x": 8,
      "y": 9,
      "z": -8,
      "name": "Wood_Beech_Trunk",
      "support": 15
    },
    {
      "x": 8,
      "y": 10,
      "z": -8,
      "name": "Wood_Softwood_Roof",
      "rotation": 1
    },
    {
      "x": 8,
      "y": 1,
      "z": -7,
      "name": "Rock_Stone_Cobble_Mossy"
    },
    {
      "x": 8,
      "y": 2,
      "z": -7,
      "name": "Rock_Stone_Brick"
    },
    {
      "x": 8,
      "y": 3,
      "z": -7,
      "name": "*Wood_Village_Wall_Full_State_Definitions_Bottom"
    },
    {
      "x": 8,
      "y": 4,
      "z": -7,
      "name": "*Wood_Village_Wall_Full_State_Definitions_Top"
    },
    {
      "x": 8,
      "y": 5,
      "z": -7,
      "name": "Wood_Beech_Trunk",
      "support": 15,
      "rotation": 4
    },
    {
      "x": 8,
      "y": 6,
      "z": -7,
      "name": "*Wood_Village_Wall_Full_State_Definitions_Bottom"
    },
    {
      "x": 8,
      "y": 7,
      "z": -7,
      "name": "*Wood_Village_Wall_Full_State_Definitions_Middle"
    },
    {
      "x": 8,
      "y": 8,
      "z": -7,
      "name": "*Wood_Village_Wall_Full_State_Definitions_Top"
    },
    {
      "x": 8,
      "y": 9,
      "z": -7,
      "name": "Wood_Beech_Trunk",
      "support": 15,
      "rotation": 4
    },
    {
      "x": 8,
      "y": 10,
      "z": -7,
      "name": "Wood_Softwood_Roof",
      "rotation": 1
    },
    {
      "x": 8,
      "y": 1,
      "z": -6,
      "name": "Rock_Stone_Cobble"
    },
    {
      "x": 8,
      "y": 2,
      "z": -6,
      "name": "Rock_Stone_Brick_Mossy"
    },
    {
      "x": 8,
      "y": 3,
      "z": -6,
      "name": "Furniture_Village_Window",
      "rotation": 1
    },
    {
      "x": 8,
      "y": 4,
      "z": -6,
      "name": "Furniture_Village_Window",
      "rotation": 1
    },
    {
      "x": 8,
      "y": 5,
      "z": -6,
      "name": "Wood_Beech_Trunk",
      "support": 15,
      "rotation": 4
    },
    {
      "x": 8,
      "y": 6,
      "z": -6,
      "name": "Wood_Village_Wall_Full"
    },
    {
      "x": 8,
      "y": 7,
      "z": -6,
      "name": "Furniture_Village_Window",
      "rotation": 1
    },
    {
      "x": 8,
      "y": 8,
      "z": -6,
      "name": "Wood_Village_Wall_Full"
    },
    {
      "x": 8,
      "y": 9,
      "z": -6,
      "name": "Wood_Beech_Trunk",
      "support": 15,
      "rotation": 4
    },
    {
      "x": 8,
      "y": 10,
      "z": -6,
      "name": "Wood_Softwood_Roof",
      "rotation": 1
    },
    {
      "x": 8,
      "y": 1,
      "z": -5,
      "name": "Rock_Stone_Cobble_Mossy"
    },
    {
      "x": 8,
      "y": 2,
      "z": -5,
      "name": "Rock_Stone_Brick"
    },
    {
      "x": 8,
      "y": 3,
      "z": -5,
      "name": "*Wood_Village_Wall_Full_State_Definitions_Bottom"
    },
    {
      "x": 8,
      "y": 4,
      "z": -5,
      "name": "*Wood_Village_Wall_Full_State_Definitions_Top"
    },
    {
      "x": 8,
      "y": 5,
      "z": -5,
      "name": "Wood_Beech_Trunk",
      "support": 15,
      "rotation": 4
    },
    {
      "x": 8,
      "y": 6,
      "z": -5,
      "name": "*Wood_Village_Wall_Full_State_Definitions_Bottom"
    },
    {
      "x": 8,
      "y": 7,
      "z": -5,
      "name": "*Wood_Village_Wall_Full_State_Definitions_Middle"
    },
    {
      "x": 8,
      "y": 8,
      "z": -5,
      "name": "*Wood_Village_Wall_Full_State_Definitions_Top"
    },
    {
      "x": 8,
      "y": 9,
      "z": -5,
      "name": "Wood_Beech_Trunk",
      "support": 15,
      "rotation": 4
    },
    {
      "x": 8,
      "y": 10,
      "z": -5,
      "name": "Wood_Softwood_Roof",
      "rotation": 1
    },
    {
      "x": 8,
      "y": 1,
      "z": -4,
      "name": "Rock_Stone_Cobble"
    },
    {
      "x": 8,
      "y": 2,
      "z": -4,
      "name": "Rock_Stone_Brick"
    },
    {
      "x": 8,
      "y": 3,
      "z": -4,
      "name": "Furniture_Village_Window",
      "rotation": 1
    },
    {
      "x": 8,
      "y": 4,
      "z": -4,
      "name": "Furniture_Village_Window",
      "rotation": 1
    },
    {
      "x": 8,
      "y": 5,
      "z": -4,
      "name": "Wood_Beech_Trunk",
      "support": 15,
      "rotation": 4
    },
    {
      "x": 8,
      "y": 6,
      "z": -4,
      "name": "Wood_Village_Wall_Full"
    },
    {
      "x": 8,
      "y": 7,
      "z": -4,
      "name": "Furniture_Village_Window",
      "rotation": 1
    },
    {
      "x": 8,
      "y": 8,
      "z": -4,
      "name": "Wood_Village_Wall_Full"
    },
    {
      "x": 8,
      "y": 9,
      "z": -4,
      "name": "Wood_Beech_Trunk",
      "support": 15,
      "rotation": 4
    },
    {
      "x": 8,
      "y": 10,
      "z": -4,
      "name": "Wood_Softwood_Roof",
      "rotation": 1
    },
    {
      "x": 8,
      "y": 1,
      "z": -3,
      "name": "Rock_Stone_Cobble_Mossy"
    },
    {
      "x": 8,
      "y": 2,
      "z": -3,
      "name": "Rock_Stone_Brick"
    },
    {
      "x": 8,
      "y": 3,
      "z": -3,
      "name": "*Wood_Village_Wall_Full_State_Definitions_Bottom"
    },
    {
      "x": 8,
      "y": 4,
      "z": -3,
      "name": "*Wood_Village_Wall_Full_State_Definitions_Top"
    },
    {
      "x": 8,
      "y": 5,
      "z": -3,
      "name": "Wood_Beech_Trunk",
      "support": 15,
      "rotation": 4
    },
    {
      "x": 8,
      "y": 6,
      "z": -3,
      "name": "*Wood_Village_Wall_Full_State_Definitions_Bottom"
    },
    {
      "x": 8,
      "y": 7,
      "z": -3,
      "name": "*Wood_Village_Wall_Full_State_Definitions_Middle"
    },
    {
      "x": 8,
      "y": 8,
      "z": -3,
      "name": "*Wood_Village_Wall_Full_State_Definitions_Top"
    },
    {
      "x": 8,
      "y": 9,
      "z": -3,
      "name": "Wood_Beech_Trunk",
      "support": 15,
      "rotation": 4
    },
    {
      "x": 8,
      "y": 10,
      "z": -3,
      "name": "Wood_Softwood_Roof",
      "rotation": 1
    },
    {
      "x": 8,
      "y": 1,
      "z": -2,
      "name": "Rock_Stone_Cobble"
    },
    {
      "x": 8,
      "y": 2,
      "z": -2,
      "name": "Wood_Beech_Trunk",
      "support": 15
    },
    {
      "x": 8,
      "y": 3,
      "z": -2,
      "name": "Wood_Beech_Trunk",
      "support": 15
    },
    {
      "x": 8,
      "y": 4,
      "z": -2,
      "name": "Wood_Beech_Trunk",
      "support": 15
    },
    {
      "x": 8,
      "y": 5,
      "z": -2,
      "name": "Wood_Beech_Trunk",
      "support": 15
    },
    {
      "x": 8,
      "y": 6,
      "z": -2,
      "name": "Wood_Beech_Trunk",
      "support": 15
    },
    {
      "x": 8,
      "y": 7,
      "z": -2,
      "name": "Wood_Beech_Trunk",
      "support": 15
    },
    {
      "x": 8,
      "y": 8,
      "z": -2,
      "name": "Wood_Beech_Trunk",
      "support": 15
    },
    {
      "x": 8,
      "y": 9,
      "z": -2,
      "name": "Wood_Beech_Trunk",
      "support": 15
    },
    {
      "x": 8,
      "y": 10,
      "z": -2,
      "name": "Wood_Softwood_Roof",
      "rotation": 1
    },
    {
      "x": 8,
      "y": 1,
      "z": -1,
      "name": "Rock_Stone_Cobble"
    },
    {
      "x": 8,
      "y": 4,
      "z": -1,
      "name": "Plant_Vine_Wall",
      "support": 15
    },
    {
      "x": 8,
      "y": 9,
      "z": -1,
      "name": "Wood_Beech_Branch_Corner",
      "support": 15
    },
    {
      "x": 8,
      "y": 10,
      "z": -1,
      "name": "Wood_Softwood_Roof",
      "rotation": 1
    },
    {
      "x": 9,
      "y": 1,
      "z": -9,
      "name": "Rock_Stone_Cobble"
    },
    {
      "x": 9,
      "y": 9,
      "z": -9,
      "name": "Wood_Softwood_Roof_Hollow",
      "rotation": 1
    },
    {
      "x": 9,
      "y": 1,
      "z": -8,
      "name": "Rock_Stone_Cobble"
    },
    {
      "x": 9,
      "y": 3,
      "z": -8,
      "name": "Plant_Vine_Wall",
      "support": 15,
      "rotation": 1
    },
    {
      "x": 9,
      "y": 8,
      "z": -8,
      "name": "Wood_Beech_Branch_Corner",
      "support": 15,
      "rotation": 1
    },
    {
      "x": 9,
      "y": 9,
      "z": -8,
      "name": "Wood_Softwood_Roof",
      "rotation": 1
    },
    {
      "x": 9,
      "y": 1,
      "z": -7,
      "name": "Rock_Stone_Cobble"
    },
    {
      "x": 9,
      "y": 9,
      "z": -7,
      "name": "Wood_Softwood_Roof_Hollow",
      "rotation": 1
    },
    {
      "x": 9,
      "y": 1,
      "z": -6,
      "name": "Rock_Stone_Cobble_Mossy"
    },
    {
      "x": 9,
      "y": 9,
      "z": -6,
      "name": "Wood_Softwood_Roof_Hollow",
      "rotation": 1
    },
    {
      "x": 9,
      "y": 1,
      "z": -5,
      "name": "Rock_Stone_Cobble_Mossy"
    },
    {
      "x": 9,
      "y": 6,
      "z": -5,
      "name": "Plant_Vine_Wall",
      "support": 15,
      "rotation": 1
    },
    {
      "x": 9,
      "y": 9,
      "z": -5,
      "name": "Wood_Softwood_Roof_Hollow",
      "rotation": 1
    },
    {
      "x": 9,
      "y": 1,
      "z": -4,
      "name": "Rock_Stone_Cobble"
    },
    {
      "x": 9,
      "y": 9,
      "z": -4,
      "name": "Wood_Softwood_Roof_Hollow",
      "rotation": 1
    },
    {
      "x": 9,
      "y": 1,
      "z": -3,
      "name": "Rock_Stone_Cobble"
    },
    {
      "x": 9,
      "y": 9,
      "z": -3,
      "name": "Wood_Softwood_Roof_Hollow",
      "rotation": 1
    },
    {
      "x": 9,
      "y": 1,
      "z": -2,
      "name": "Rock_Stone_Cobble"
    },
    {
      "x": 9,
      "y": 8,
      "z": -2,
      "name": "Wood_Beech_Branch_Corner",
      "support": 15,
      "rotation": 1
    },
    {
      "x": 9,
      "y": 9,
      "z": -2,
      "name": "Wood_Softwood_Roof",
      "rotation": 1
    },
    {
      "x": 9,
      "y": 1,
      "z": -1,
      "name": "Rock_Stone_Cobble"
    },
    {
      "x": 9,
      "y": 9,
      "z": -1,
      "name": "Wood_Softwood_Roof_Hollow",
      "rotation": 1
    }
  ]
}