{
  "version": 8,
  "blockIdVersion": 11,
  "anchorX": 0,
  "anchorY": 0,
  "anchorZ": 0,
  "blocks": [
    {
      "x": 1,
      "y": 1,
      "z": -9,
      "name": "Rock_Stone_Cobble"
    },
    {
      "x": 1,
      "y": 5,
      "z": -9,
      "name": "Wood_Softwood_Roof_Hollow",
      "rotation": 3
    },
    {
      "x": 1,
      "y": 1,
      "z": -8,
      "name": "Rock_Stone_Cobble"
    },
    {
      "x": 1,
      "y": 5,
      "z": -8,
      "name": "Wood_Softwood_Roof_Hollow",
      "rotation": 3
    },
    {
      "x": 1,
      "y": 1,
      "z": -7,
      "name": "Rock_Stone_Cobble_Mossy"
    },
    {
      "x": 1,
      "y": 5,
      "z": -7,
      "name": "Wood_Softwood_Roof_Hollow",
      "rotation": 3
    },
    {
      "x": 1,
      "y": 1,
      "z": -6,
      "name": "Rock_Stone_Cobble"
    },
    {
      "x": 1,
      "y": 5,
      "z": -6,
      "name": "Wood_Softwood_Roof_Hollow",
      "rotation": 3
    },
    {
      "x": 1,
      "y": 1,
      "z": -5,
      "name": "Rock_Stone_Cobble"
    },
    {
      "x": 1,
      "y": 3,
      "z": -5,
      "name": "Plant_Vine_Wall",
      "support": 15,
      "rotation": 3
    },
    {
      "x": 1,
      "y": 5,
      "z": -5,
      "name": "Wood_Softwood_Roof_Hollow",
      "rotation": 3
    },
    {
      "x": 1,
      "y": 1,
      "z": -4,
      "name": "Rock_Stone_Cobble"
    },
    {
      "x": 1,
      "y": 5,
      "z": -4,
      "name": "Wood_Softwood_Roof_Hollow",
      "rotation": 3
    },
    {
      "x": 1,
      "y": 1,
      "z": -3,
      "name": "Rock_Stone_Cobble"
    },
    {
      "x": 1,
      "y": 5,
      "z": -3,
      "name": "Wood_Softwood_Roof_Hollow",
      "rotation": 3
    },
    {
      "x": 1,
      "y": 1,
      "z": -2,
      "name": "Rock_Stone_Cobble"
    },
    {
      "x": 1,
      "y": 5,
      "z": -2,
      "name": "Wood_Softwood_Roof_Hollow",
      "rotation": 3
    },
    {
      "x": 1,
      "y": 1,
      "z": -1,
      "name": "Rock_Stone_Cobble"
    },
    {
      "x": 1,
      "y": 5,
      "z": -1,
      "name": "Wood_Softwood_Roof_Hollow",
      "rotation": 3
    },
    {
      "x": 2,
      "y": 1,
      "z": -9,
      "name": "Rock_Stone_Cobble"
    },
    {
      "x": 2,
      "y": 5,
      "z": -9,
      "name": "Wood_Beech_Branch_Corner",
      "support": 15,
      "rotation": 2
    },
    {
      "x": 2,
      "y": 6,
      "z": -9,
      "name": "Wood_Softwood_Roof",
      "rotation": 3
    },
    {
      "x": 2,
      "y": 1,
      "z": -8,
      "name": "Rock_Stone_Cobble"
    },
    {
      "x": 2,
      "y": 2,
      "z": -8,
      "name": "Wood_Beech_Trunk",
      "support": 15
    },
    {
      "x": 2,
      "y": 3,
      "z": -8,
      "name": "Wood_Beech_Trunk",
      "support": 15
    },
    {
      "x": 2,
      "y": 4,
      "z": -8,
      "name": "Wood_Beech_Trunk",
      "support": 15
    },
    {
      "x": 2,
      "y": 5,
      "z": -8,
      "name": "Wood_Beech_Trunk",
      "support": 15,
      "rotation": 4
    },
    {
      "x": 2,
      "y": 6,
      "z": -8,
      "name": "Wood_Softwood_Roof",
      "rotation": 3
    },
    {
      "x": 2,
      "y": 1,
      "z": -7,
      "name": "Rock_Stone_Cobble_Mossy"
    },
    {
      "x": 2,
      "y": 2,
      "z": -7,
      "name": "Rock_Stone_Brick_Mossy"
    },
    {
      "x": 2,
      "y": 3,
      "z": -7,
      "name": "*Wood_Village_Wall_Full_State_Definitions_Bottom"
    },
    {
      "x": 2,
      "y": 4,
      "z": -7,
      "name": "*Wood_Village_Wall_Full_State_Definitions_Top"
    },
    {
      "x": 2,
      "y": 5,
      "z": -7,
      "name": "Wood_Beech_Trunk",
      "support": 15,
      "rotation": 4
    },
    {
      "x": 2,
      "y": 6,
      "z": -7,
      "name": "Wood_Softwood_Roof",
      "rotation": 3
    },
    {
      "x": 2,
      "y": 1,
      "z": -6,
      "name": "Rock_Stone_Cobble"
    },
    {
      "x": 2,
      "y": 2,
      "z": -6,
      "name": "Rock_Stone_Brick"
    },
    {
      "x": 2,
      "y": 3,
      "z": -6,
      "name": "Furniture_Village_Window",
      "rotation": 1
    },
    {
      "x": 2,
      "y": 4,
      "z": -6,
      "name": "Furniture_Village_Window",
      "rotation": 1
    },
    {
      "x": 2,
      "y": 5,
      "z": -6,
      "name": "Wood_Beech_Trunk",
      "support": 15,
      "rotation": 4
    },
    {
      "x": 2,
      "y": 6,
      "z": -6,
      "name": "Wood_Softwood_Roof",
      "rotation": 3
    },
    {
      "x": 2,
      "y": 1,
      "z": -5,
      "name": "Rock_Stone_Cobble"
    },
    {
      "x": 2,
      "y": 2,
      "z": -5,
      "name": "Rock_Stone_Brick"
    },
    {
      "x": 2,
      "y": 3,
      "z": -5,
      "name": "*Wood_Village_Wall_Full_State_Definitions_Bottom"
    },
    {
      "x": 2,
      "y": 4,
      "z": -5,
      "name": "*Wood_Village_Wall_Full_State_Definitions_Top"
    },
    {
      "x": 2,
      "y": 5,
      "z": -5,
      "name": "Wood_Beech_Trunk",
      "support": 15,
      "rotation": 4
    },
    {
      "x": 2,
      "y": 6,
      "z": -5,
      "name": "Wood_Softwood_Roof",
      "rotation": 3
    },
    {
      "x": 2,
      "y": 1,
      "z": -4,
      "name": "Rock_Stone_Cobble"
    },
    {
      "x": 2,
      "y": 2,
      "z": -4,
      "name": "Rock_Stone_Brick"
    },
    {
      "x": 2,
      "y": 3,
      "z": -4,
      "name": "Furniture_Village_Window",
      "rotation": 1
    },
    {
      "x": 2,
      "y": 4,
      "z": -4,
      "name": "Furniture_Village_Window",
      "rotation": 1
    },
    {
      "x": 2,
      "y": 5,
      "z": -4,
      "name": "Wood_Beech_Trunk",
      "support": 15,
      "rotation": 4
    },
    {
      "x": 2,
      "y": 6,
      "z": -4,
      "name": "Wood_Softwood_Roof",
      "rotation": 3
    },
    {
      "x": 2,
      "y": 1,
      "z": -3,
      "name": "Rock_Stone_Cobble_Mossy"
    },
    {
      "x": 2,
      "y": 2,
      "z": -3,
      "name": "Rock_Stone_Brick"
    },
    {
      "x": 2,
      "y": 3,
      "z": -3,
      "name": "*Wood_Village_Wall_Full_State_Definitions_Bottom"
    },
    {
      "x": 2,
      "y": 4,
      "z": -3,
      "name": "*Wood_Village_Wall_Full_State_Definitions_Top"
    },
    {
      "x": 2,
      "y": 5,
      "z": -3,
      "name": "Wood_Beech_Trunk",
      "support": 15,
      "rotation": 4
    },
    {
      "x": 2,
      "y": 6,
      "z": -3,
      "name": "Wood_Softwood_Roof",
      "rotation": 3
    },
    {
      "x": 2,
      "y": 1,
      "z": -2,
      "name": "Rock_Stone_Cobble"
    },
    {
      "x": 2,
      "y": 2,
      "z": -2,
      "name": "Wood_Beech_Trunk",
      "support": 15
    },
    {
      "x": 2,
      "y": 3,
      "z": -2,
      "name": "Wood_Beech_Trunk",
      "support": 15
    },
    {
      "x": 2,
      "y": 4,
      "z": -2,
      "name": "Wood_Beech_Trunk",
      "support": 15
    },
    {
      "x": 2,
      "y": 5,
      "z": -2,
      "name": "Wood_Beech_Trunk",
      "support": 15
    },
    {
      "x": 2,
      "y": 6,
      "z": -2,
      "name": "Wood_Softwood_Roof",
      "rotation": 3
    },
    {
      "x": 2,
      "y": 1,
      "z": -1,
      "name": "Rock_Stone_Cobble"
    },
    {
      "x": 2,
      "y": 5,
      "z": -1,
      "name": "Wood_Beech_Branch_Corner",
      "support": 15
    },
    {
      "x": 2,
      "y": 6,
      "z": -1,
      "name": "Wood_Softwood_Roof",
      "rotation": 3
    },
    {
      "x": 3,
      "y": 1,
      "z": -9,
      "name": "Rock_Stone_Cobble"
    },
    {
      "x": 3,
      "y": 5,
      "z": -9,
      "name": "Plant_Vine_Wall",
      "support": 15,
      "rotation": 2
    },
    {
      "x": 3,
      "y": 6,
      "z": -9,
      "name": "Wood_Softwood_Stairs",
      "rotation": 11
    },
    {
      "x": 3,
      "y": 7,
      "z": -9,
      "name": "Wood_Softwood_Roof",
      "rotation": 3
    },
    {
      "x": 3,
      "y": 1,
      "z": -8,
      "name": "Rock_Stone_Cobble"
    },
    {
      "x": 3,
      "y": 2,
      "z": -8,
      "name": "Rock_Stone_Brick"
    },
    {
      "x": 3,
      "y": 3,
      "z": -8,
      "name": "*Wood_Village_Wall_Full_State_Definitions_Bottom"
    },
    {
      "x": 3,
      "y": 4,
      "z": -8,
      "name": "*Wood_Village_Wall_Full_State_Definitions_Top"
    },
    {
      "x": 3,
      "y": 5,
      "z": -8,
      "name": "Wood_Beech_Trunk",
      "support": 15,
      "rotation": 5
    },
    {
      "x": 3,
      "y": 6,
      "z": -8,
      "name": "Wood_Village_Wall_Full"
    },
    {
      "x": 3,
      "y": 7,
      "z": -8,
      "name": "Wood_Softwood_Roof",
      "rotation": 3
    },
    {
      "x": 3,
      "y": 1,
      "z": -7,
      "name": "Wood_Softwood_Planks"
    },
    {
      "x": 3,
      "y": 2,
      "z": -7,
      "name": "Furniture_Village_Crate"
    },
    {
      "x": 3,
      "y": 6,
      "z": -7,
      "name": "Wood_Softwood_Stairs",
      "rotation": 11
    },
    {
      "x": 3,
      "y": 7,
      "z": -7,
      "name": "Wood_Softwood_Roof",
      "rotation": 3
    },
    {
      "x": 3,
      "y": 1,
      "z": -6,
      "name": "Wood_Softwood_Planks"
    },
    {
      "x": 3,
      "y": 6,
      "z": -6,
      "name": "Wood_Softwood_Stairs",
      "rotation": 11
    },
    {
      "x": 3,
      "y": 7,
      "z": -6,
      "name": "Wood_Softwood_Roof",
      "rotation": 3
    },
    {
      "x": 3,
      "y": 1,
      "z": -5,
      "name": "Wood_Softwood_Planks"
    },
    {
      "x": 3,
      "y": 2,
      "z": -5,
      "name": "Wood_Deadwood_Planks"
    },
    {
      "x": 3,
      "y": 3,
      "z": -5,
      "name": "Furniture_Human_Ruins_Candle"
    },
    {
      "x": 3,
      "y": 4,
      "z": -5,
      "name": "Furniture_Human_Ruins_Candle",
      "filler": 1024
    },
    {
      "x": 3,
      "y": 6,
      "z": -5,
      "name": "Wood_Softwood_Stairs",
      "rotation": 11
    },
    {
      "x": 3,
      "y": 7,
      "z": -5,
      "name": "Wood_Softwood_Roof",
      "rotation": 3
    },
    {
      "x": 3,
      "y": 1,
      "z": -4,
      "name": "Wood_Softwood_Planks"
    },
    {
      "x": 3,
      "y": 2,
      "z": -4,
      "name": "Furniture_Village_Crate"
    },
    {
      "x": 3,
      "y": 6,
      "z": -4,
      "name": "Wood_Softwood_Stairs",
      "rotation": 11
    },
    {
      "x": 3,
      "y": 7,
      "z": -4,
      "name": "Wood_Softwood_Roof",
      "rotation": 3
    },
    {
      "x": 3,
      "y": 1,
      "z": -3,
      "name": "Wood_Softwood_Planks"
    },
    {
      "x": 3,
      "y": 2,
      "z": -3,
      "name": "Furniture_Tavern_Barrel"
    },
    {
      "x": 3,
      "y": 6,
      "z": -3,
      "name": "Wood_Softwood_Stairs",
      "rotation": 11
    },
    {
      "x": 3,
      "y": 7,
      "z": -3,
      "name": "Wood_Softwood_Roof",
      "rotation": 3
    },
    {
      "x": 3,
      "y": 1,
      "z": -2,
      "name": "Rock_Stone_Cobble"
    },
    {
      "x": 3,
      "y": 2,
      "z": -2,
      "name": "Rock_Stone_Brick"
    },
    {
      "x": 3,
      "y": 3,
      "z": -2,
      "name": "*Wood_Village_Wall_Full_State_Definitions_Bottom"
    },
    {
      "x": 3,
      "y": 4,
      "z": -2,
      "name": "*Wood_Village_Wall_Full_State_Definitions_Top"
    },
    {
      "x": 3,
      "y": 5,
      "z": -2,
      "name": "Wood_Beech_Trunk",
      "support": 15,
      "rotation": 5
    },
    {
      "x": 3,
      "y": 6,
      "z": -2,
      "name": "Wood_Village_Wall_Full"
    },
    {
      "x": 3,
      "y": 7,
      "z": -2,
      "name": "Wood_Softwood_Roof",
      "rotation": 3
    },
    {
      "x": 3,
      "y": 1,
      "z": -1,
      "name": "Rock_Stone_Cobble"
    },
    {
      "x": 3,
      "y": 4,
      "z": -1,
      "name": "Plant_Vine_Wall",
      "support": 15
    },
    {
      "x": 3,
      "y": 6,
      "z": -1,
      "name": "Wood_Softwood_Stairs",
      "rotation": 11
    },
    {
      "x": 3,
      "y": 7,
      "z": -1,
      "name": "Wood_Softwood_Roof",
      "rotation": 3
    },
    {
      "x": 4,
      "y": 1,
      "z": -9,
      "name": "Rock_Stone_Cobble"
    },
    {
      "x": 4,
      "y": 5,
      "z": -9,
      "name": "Wood_Beech_Branch_Short",
      "support": 15,
      "rotation": 2
    },
    {
      "x": 4,
      "y": 7,
      "z": -9,
      "name": "Wood_Softwood_Stairs",
      "rotation": 11
    },
    {
      "x": 4,
      "y": 8,
      "z": -9,
      "name": "Wood_Softwood_Roof_Flat"
    },
    {
      "x": 4,
      "y": 1,
      "z": -8,
      "name": "Rock_Stone_Cobble"
    },
    {
      "x": 4,
      "y": 2,
      "z": -8,
      "name": "Rock_Stone_Brick"
    },
    {
      "x": 4,
      "y": 3,
      "z": -8,
      "name": "Furniture_Village_Window"
    },
    {
      "x": 4,
      "y": 4,
      "z": -8,
      "name": "Furniture_Village_Window"
    },
    {
      "x": 4,
      "y": 5,
      "z": -8,
      "name": "Wood_Beech_Trunk",
      "support": 15,
      "rotation": 5
    },
    {
      "x": 4,
      "y": 6,
      "z": -8,
      "name": "*Wood_Village_Wall_Full_State_Definitions_Bottom"
    },
    {
      "x": 4,
      "y": 7,
      "z": -8,
      "name": "*Wood_Village_Wall_Full_State_Definitions_Top"
    },
    {
      "x": 4,
      "y": 8,
      "z": -8,
      "name": "Wood_Softwood_Roof_Flat"
    },
    {
      "x": 4,
      "y": 1,
      "z": -7,
      "name": "Wood_Softwood_Planks"
    },
    {
      "x": 4,
      "y": 7,
      "z": -7,
      "name": "Wood_Softwood_Stairs",
      "rotation": 11
    },
    {
      "x": 4,
      "y": 8,
      "z": -7,
      "name": "Wood_Softwood_Roof_Flat"
    },
    {
      "x": 4,
      "y": 1,
      "z": -6,
      "name": "Wood_Softwood_Planks"
    },
    {
      "x": 4,
      "y": 7,
      "z": -6,
      "name": "Wood_Softwood_Stairs",
      "rotation": 11
    },
    {
      "x": 4,
      "y": 8,
      "z": -6,
      "name": "Wood_Softwood_Roof_Flat"
    },
    {
      "x": 4,
      "y": 9,
      "z": -6,
      "name": "Cloth_Block_Wool_Black"
    },
    {
      "x": 4,
      "y": 10,
      "z": -6,
      "name": "Cloth_Block_Wool_Black"
    },
    {
      "x": 4,
      "y": 11,
      "z": -6,
      "name": "Cloth_Block_Wool_Black"
    },
    {
      "x": 4,
      "y": 1,
      "z": -5,
      "name": "Wood_Softwood_Planks"
    },
    {
      "x": 4,
      "y": 2,
      "z": -5,
      "name": "Wood_Deadwood_Planks"
    },
    {
      "x": 4,
      "y": 3,
      "z": -5,
      "name": "Aetherhaven_Shop_Spot",
      "components": {
        "Components": {
          "AetherhavenShopSpotBlock": {
            "SpotId": "1140bfcb-5615-43fd-afe7-90bbe725ee38",
            "TownId": "d87b9d18-a6de-42a7-9697-90f4c2aa0d9f",
            "PlotId": "00000000-0000-0000-0000-000000000000",
            "PlayerControlled": false,
            "LootTableId": "pyro_powder",
            "Configured": true
          },
          "PlacedByInteraction": {
            "WhoPlacedUuid": {
              "$binary": "v7RyWIT/TYKnXA2XcxdQtw==",
              "$type": "04"
            }
          }
        }
      }
    },
    {
      "x": 4,
      "y": 7,
      "z": -5,
      "name": "Wood_Softwood_Stairs",
      "rotation": 11
    },
    {
      "x": 4,
      "y": 8,
      "z": -5,
      "name": "Wood_Softwood_Roof_Flat"
    },
    {
      "x": 4,
      "y": 9,
      "z": -5,
      "name": "Cloth_Block_Wool_Black"
    },
    {
      "x": 4,
      "y": 10,
      "z": -5,
      "name": "Cloth_Block_Wool_Black"
    },
    {
      "x": 4,
      "y": 11,
      "z": -5,
      "name": "Cloth_Block_Wool_Black"
    },
    {
      "x": 4,
      "y": 15,
      "z": -5,
      "name": "Cloth_Block_Wool_Orange"
    },
    {
      "x": 4,
      "y": 1,
      "z": -4,
      "name": "Wood_Softwood_Planks"
    },
    {
      "x": 4,
      "y": 7,
      "z": -4,
      "name": "Wood_Softwood_Stairs",
      "rotation": 11
    },
    {
      "x": 4,
      "y": 8,
      "z": -4,
      "name": "Wood_Softwood_Roof_Flat"
    },
    {
      "x": 4,
      "y": 9,
      "z": -4,
      "name": "Cloth_Block_Wool_Black"
    },
    {
      "x": 4,
      "y": 10,
      "z": -4,
      "name": "Cloth_Block_Wool_Black"
    },
    {
      "x": 4,
      "y": 11,
      "z": -4,
      "name": "Cloth_Block_Wool_Black"
    },
    {
      "x": 4,
      "y": 1,
      "z": -3,
      "name": "Wood_Softwood_Planks"
    },
    {
      "x": 4,
      "y": 7,
      "z": -3,
      "name": "Wood_Softwood_Stairs",
      "rotation": 11
    },
    {
      "x": 4,
      "y": 8,
      "z": -3,
      "name": "Wood_Softwood_Roof_Flat"
    },
    {
      "x": 4,
      "y": 1,
      "z": -2,
      "name": "Rock_Stone_Cobble"
    },
    {
      "x": 4,
      "y": 2,
      "z": -2,
      "name": "Rock_Stone_Brick_Mossy"
    },
    {
      "x": 4,
      "y": 3,
      "z": -2,
      "name": "Furniture_Village_Window"
    },
    {
      "x": 4,
      "y": 4,
      "z": -2,
      "name": "Furniture_Village_Window"
    },
    {
      "x": 4,
      "y": 5,
      "z": -2,
      "name": "Wood_Beech_Trunk",
      "support": 15,
      "rotation": 5
    },
    {
      "x": 4,
      "y": 6,
      "z": -2,
      "name": "*Wood_Village_Wall_Full_State_Definitions_Bottom"
    },
    {
      "x": 4,
      "y": 7,
      "z": -2,
      "name": "*Wood_Village_Wall_Full_State_Definitions_Top"
    },
    {
      "x": 4,
      "y": 8,
      "z": -2,
      "name": "Wood_Softwood_Roof_Flat"
    },
    {
      "x": 4,
      "y": 1,
      "z": -1,
      "name": "Rock_Stone_Cobble"
    },
    {
      "x": 4,
      "y": 5,
      "z": -1,
      "name": "Wood_Beech_Branch_Short",
      "support": 15
    },
    {
      "x": 4,
      "y": 7,
      "z": -1,
      "name": "Wood_Softwood_Stairs",
      "rotation": 11
    },
    {
      "x": 4,
      "y": 8,
      "z": -1,
      "name": "Wood_Softwood_Roof_Flat"
    },
    {
      "x": 5,
      "y": 1,
      "z": -9,
      "name": "Rock_Stone_Cobble"
    },
    {
      "x": 5,
      "y": 7,
      "z": -9,
      "name": "Wood_Softwood_Planks_Half",
      "rotation": 8
    },
    {
      "x": 5,
      "y": 8,
      "z": -9,
      "name": "Wood_Softwood_Roof_Flat"
    },
    {
      "x": 5,
      "y": 1,
      "z": -8,
      "name": "Rock_Stone_Cobble"
    },
    {
      "x": 5,
      "y": 2,
      "z": -8,
      "name": "Rock_Stone_Brick"
    },
    {
      "x": 5,
      "y": 3,
      "z": -8,
      "name": "Furniture_Village_Window"
    },
    {
      "x": 5,
      "y": 4,
      "z": -8,
      "name": "Furniture_Village_Window"
    },
    {
      "x": 5,
      "y": 5,
      "z": -8,
      "name": "Wood_Beech_Trunk",
      "support": 15,
      "rotation": 5
    },
    {
      "x": 5,
      "y": 6,
      "z": -8,
      "name": "Furniture_Village_Window"
    },
    {
      "x": 5,
      "y": 7,
      "z": -8,
      "name": "Wood_Village_Wall_Full"
    },
    {
      "x": 5,
      "y": 8,
      "z": -8,
      "name": "Wood_Softwood_Roof_Flat"
    },
    {
      "x": 5,
      "y": 1,
      "z": -7,
      "name": "Wood_Softwood_Planks"
    },
    {
      "x": 5,
      "y": 7,
      "z": -7,
      "name": "Wood_Softwood_Planks_Half",
      "rotation": 8
    },
    {
      "x": 5,
      "y": 8,
      "z": -7,
      "name": "Wood_Softwood_Roof_Flat",
      "rotation": 2
    },
    {
      "x": 5,
      "y": 9,
      "z": -7,
      "name": "Cloth_Block_Wool_Black"
    },
    {
      "x": 5,
      "y": 10,
      "z": -7,
      "name": "Cloth_Block_Wool_Black"
    },
    {
      "x": 5,
      "y": 11,
      "z": -7,
      "name": "Cloth_Block_Wool_Black"
    },
    {
      "x": 5,
      "y": 1,
      "z": -6,
      "name": "Wood_Softwood_Planks"
    },
    {
      "x": 5,
      "y": 7,
      "z": -6,
      "name": "Wood_Softwood_Planks_Half",
      "rotation": 8
    },
    {
      "x": 5,
      "y": 8,
      "z": -6,
      "name": "Cloth_Block_Wool_Black"
    },
    {
      "x": 5,
      "y": 12,
      "z": -6,
      "name": "Cloth_Block_Wool_Black"
    },
    {
      "x": 5,
      "y": 1,
      "z": -5,
      "name": "Wood_Softwood_Planks"
    },
    {
      "x": 5,
      "y": 2,
      "z": -5,
      "name": "Wood_Deadwood_Planks"
    },
    {
      "x": 5,
      "y": 3,
      "z": -5,
      "name": "Aetherhaven_Shop_Spot",
      "components": {
        "Components": {
          "AetherhavenShopSpotBlock": {
            "SpotId": "a5989983-a7ea-46ed-a315-78193bbc7e6b",
            "TownId": "d87b9d18-a6de-42a7-9697-90f4c2aa0d9f",
            "PlotId": "00000000-0000-0000-0000-000000000000",
            "PlayerControlled": false,
            "LootTableId": "pyro_bomb",
            "Configured": true
          },
          "PlacedByInteraction": {
            "WhoPlacedUuid": {
              "$binary": "v7RyWIT/TYKnXA2XcxdQtw==",
              "$type": "04"
            }
          }
        }
      }
    },
    {
      "x": 5,
      "y": 7,
      "z": -5,
      "name": "Wood_Softwood_Planks_Half",
      "rotation": 8
    },
    {
      "x": 5,
      "y": 8,
      "z": -5,
      "name": "Cloth_Block_Wool_Black"
    },
    {
      "x": 5,
      "y": 12,
      "z": -5,
      "name": "Cloth_Block_Wool_Black"
    },
    {
      "x": 5,
      "y": 16,
      "z": -5,
      "name": "Cloth_Block_Wool_White"
    },
    {
      "x": 5,
      "y": 1,
      "z": -4,
      "name": "Wood_Softwood_Planks"
    },
    {
      "x": 5,
      "y": 7,
      "z": -4,
      "name": "Wood_Softwood_Planks_Half",
      "rotation": 8
    },
    {
      "x": 5,
      "y": 8,
      "z": -4,
      "name": "Cloth_Block_Wool_Black"
    },
    {
      "x": 5,
      "y": 12,
      "z": -4,
      "name": "Cloth_Block_Wool_Black"
    },
    {
      "x": 5,
      "y": 1,
      "z": -3,
      "name": "Wood_Softwood_Planks"
    },
    {
      "x": 5,
      "y": 7,
      "z": -3,
      "name": "Wood_Softwood_Planks_Half",
      "rotation": 8
    },
    {
      "x": 5,
      "y": 8,
      "z": -3,
      "name": "Wood_Softwood_Roof_Flat"
    },
    {
      "x": 5,
      "y": 9,
      "z": -3,
      "name": "Cloth_Block_Wool_Black"
    },
    {
      "x": 5,
      "y": 10,
      "z": -3,
      "name": "Cloth_Block_Wool_Black"
    },
    {
      "x": 5,
      "y": 11,
      "z": -3,
      "name": "Cloth_Block_Wool_Black"
    },
    {
      "x": 5,
      "y": 1,
      "z": -2,
      "name": "Rock_Stone_Cobble_Mossy"
    },
    {
      "x": 5,
      "y": 2,
      "z": -2,
      "name": "Rock_Stone_Brick"
    },
    {
      "x": 5,
      "y": 3,
      "z": -2,
      "name": "Furniture_Village_Window"
    },
    {
      "x": 5,
      "y": 4,
      "z": -2,
      "name": "Furniture_Village_Window"
    },
    {
      "x": 5,
      "y": 5,
      "z": -2,
      "name": "Wood_Beech_Trunk",
      "support": 15,
      "rotation": 5
    },
    {
      "x": 5,
      "y": 6,
      "z": -2,
      "name": "Furniture_Village_Window"
    },
    {
      "x": 5,
      "y": 7,
      "z": -2,
      "name": "Wood_Village_Wall_Full"
    },
    {
      "x": 5,
      "y": 8,
      "z": -2,
      "name": "Wood_Softwood_Roof_Flat"
    },
    {
      "x": 5,
      "y": 1,
      "z": -1,
      "name": "Rock_Stone_Cobble_Mossy"
    },
    {
      "x": 5,
      "y": 7,
      "z": -1,
      "name": "Wood_Softwood_Planks_Half",
      "rotation": 8
    },
    {
      "x": 5,
      "y": 8,
      "z": -1,
      "name": "Wood_Softwood_Roof_Flat"
    },
    {
      "x": 6,
      "y": 1,
      "z": -9,
      "name": "Rock_Stone_Cobble_Mossy"
    },
    {
      "x": 6,
      "y": 5,
      "z": -9,
      "name": "Wood_Beech_Branch_Short",
      "support": 15,
      "rotation": 2
    },
    {
      "x": 6,
      "y": 7,
      "z": -9,
      "name": "Wood_Softwood_Planks_Half",
      "rotation": 8
    },
    {
      "x": 6,
      "y": 8,
      "z": -9,
      "name": "Wood_Softwood_Roof_Flat"
    },
    {
      "x": 6,
      "y": 1,
      "z": -8,
      "name": "Rock_Stone_Cobble"
    },
    {
      "x": 6,
      "y": 2,
      "z": -8,
      "name": "Rock_Stone_Brick"
    },
    {
      "x": 6,
      "y": 3,
      "z": -8,
      "name": "*Wood_Village_Wall_Full_State_Definitions_Bottom"
    },
    {
      "x": 6,
      "y": 4,
      "z": -8,
      "name": "*Wood_Village_Wall_Full_State_Definitions_Top"
    },
    {
      "x": 6,
      "y": 5,
      "z": -8,
      "name": "Wood_Beech_Trunk",
      "support": 15,
      "rotation": 5
    },
    {
      "x": 6,
      "y": 6,
      "z": -8,
      "name": "Furniture_Village_Window"
    },
    {
      "x": 6,
      "y": 7,
      "z": -8,
      "name": "Wood_Village_Wall_Full"
    },
    {
      "x": 6,
      "y": 8,
      "z": -8,
      "name": "Wood_Softwood_Roof_Flat"
    },
    {
      "x": 6,
      "y": 9,
      "z": -8,
      "name": "Cloth_Block_Wool_Black"
    },
    {
      "x": 6,
      "y": 10,
      "z": -8,
      "name": "Cloth_Block_Wool_Black"
    },
    {
      "x": 6,
      "y": 11,
      "z": -8,
      "name": "Cloth_Block_Wool_Black"
    },
    {
      "x": 6,
      "y": 1,
      "z": -7,
      "name": "Wood_Softwood_Planks"
    },
    {
      "x": 6,
      "y": 2,
      "z": -7,
      "name": "Wood_Deadwood_Planks"
    },
    {
      "x": 6,
      "y": 3,
      "z": -7,
      "name": "Wood_Deadwood_Stairs",
      "rotation": 3
    },
    {
      "x": 6,
      "y": 7,
      "z": -7,
      "name": "Wood_Softwood_Planks_Half",
      "rotation": 8
    },
    {
      "x": 6,
      "y": 8,
      "z": -7,
      "name": "Cloth_Block_Wool_Black"
    },
    {
      "x": 6,
      "y": 12,
      "z": -7,
      "name": "Cloth_Block_Wool_Black"
    },
    {
      "x": 6,
      "y": 1,
      "z": -6,
      "name": "Wood_Softwood_Planks"
    },
    {
      "x": 6,
      "y": 13,
      "z": -6,
      "name": "Cloth_Block_Wool_Black"
    },
    {
      "x": 6,
      "y": 1,
      "z": -5,
      "name": "Wood_Softwood_Planks"
    },
    {
      "x": 6,
      "y": 2,
      "z": -5,
      "name": "Wood_Deadwood_Planks"
    },
    {
      "x": 6,
      "y": 3,
      "z": -5,
      "name": "Aetherhaven_Shop_Spot",
      "components": {
        "Components": {
          "AetherhavenShopSpotBlock": {
            "SpotId": "4d96de10-48ea-4e9e-aabb-a4cd917b5bfc",
            "TownId": "d87b9d18-a6de-42a7-9697-90f4c2aa0d9f",
            "PlotId": "00000000-0000-0000-0000-000000000000",
            "PlayerControlled": false,
            "LootTableId": "pyro_bomb",
            "Configured": true
          },
          "PlacedByInteraction": {
            "WhoPlacedUuid": {
              "$binary": "v7RyWIT/TYKnXA2XcxdQtw==",
              "$type": "04"
            }
          }
        }
      }
    },
    {
      "x": 6,
      "y": 13,
      "z": -5,
      "name": "Cloth_Block_Wool_Black"
    },
    {
      "x": 6,
      "y": 16,
      "z": -5,
      "name": "Cloth_Block_Wool_White"
    },
    {
      "x": 6,
      "y": 1,
      "z": -4,
      "name": "Wood_Softwood_Planks"
    },
    {
      "x": 6,
      "y": 13,
      "z": -4,
      "name": "Cloth_Block_Wool_Black"
    },
    {
      "x": 6,
      "y": 1,
      "z": -3,
      "name": "Wood_Softwood_Planks"
    },
    {
      "x": 6,
      "y": 7,
      "z": -3,
      "name": "Wood_Softwood_Planks_Half",
      "rotation": 8
    },
    {
      "x": 6,
      "y": 8,
      "z": -3,
      "name": "Cloth_Block_Wool_Black"
    },
    {
      "x": 6,
      "y": 12,
      "z": -3,
      "name": "Cloth_Block_Wool_Black"
    },
    {
      "x": 6,
      "y": 1,
      "z": -2,
      "name": "Rock_Stone_Cobble"
    },
    {
      "x": 6,
      "y": 2,
      "z": -2,
      "name": "Rock_Stone_Brick"
    },
    {
      "x": 6,
      "y": 3,
      "z": -2,
      "name": "*Wood_Village_Wall_Full_State_Definitions_Bottom"
    },
    {
      "x": 6,
      "y": 4,
      "z": -2,
      "name": "*Wood_Village_Wall_Full_State_Definitions_Top"
    },
    {
      "x": 6,
      "y": 5,
      "z": -2,
      "name": "Wood_Beech_Trunk",
      "support": 15,
      "rotation": 5
    },
    {
      "x": 6,
      "y": 6,
      "z": -2,
      "name": "Furniture_Village_Window"
    },
    {
      "x": 6,
      "y": 7,
      "z": -2,
      "name": "Wood_Village_Wall_Full"
    },
    {
      "x": 6,
      "y": 8,
      "z": -2,
      "name": "Wood_Softwood_Roof_Flat"
    },
    {
      "x": 6,
      "y": 9,
      "z": -2,
      "name": "Cloth_Block_Wool_Black"
    },
    {
      "x": 6,
      "y": 10,
      "z": -2,
      "name": "Cloth_Block_Wool_Yellow_Light"
    },
    {
      "x": 6,
      "y": 11,
      "z": -2,
      "name": "Cloth_Block_Wool_Black"
    },
    {
      "x": 6,
      "y": 1,
      "z": -1,
      "name": "Rock_Stone_Cobble"
    },
    {
      "x": 6,
      "y": 5,
      "z": -1,
      "name": "Wood_Beech_Branch_Short",
      "support": 15
    },
    {
      "x": 6,
      "y": 7,
      "z": -1,
      "name": "Wood_Softwood_Planks_Half",
      "rotation": 8
    },
    {
      "x": 6,
      "y": 8,
      "z": -1,
      "name": "Wood_Softwood_Roof_Flat"
    },
    {
      "x": 7,
      "y": 1,
      "z": -9,
      "name": "Rock_Stone_Cobble"
    },
    {
      "x": 7,
      "y": 7,
      "z": -9,
      "name": "Wood_Softwood_Planks_Half",
      "rotation": 8
    },
    {
      "x": 7,
      "y": 8,
      "z": -9,
      "name": "Wood_Softwood_Roof_Flat"
    },
    {
      "x": 7,
      "y": 9,
      "z": -9,
      "name": "Cloth_Block_Wool_Black"
    },
    {
      "x": 7,
      "y": 10,
      "z": -9,
      "name": "Cloth_Block_Wool_Black"
    },
    {
      "x": 7,
      "y": 11,
      "z": -9,
      "name": "Cloth_Block_Wool_Black"
    },
    {
      "x": 7,
      "y": 1,
      "z": -8,
      "name": "Rock_Stone_Cobble"
    },
    {
      "x": 7,
      "y": 2,
      "z": -8,
      "name": "Rock_Stone_Brick_Mossy"
    },
    {
      "x": 7,
      "y": 3,
      "z": -8,
      "name": "*Wood_Village_Wall_Full_State_Definitions_Bottom"
    },
    {
      "x": 7,
      "y": 4,
      "z": -8,
      "name": "*Wood_Village_Wall_Full_State_Definitions_Top"
    },
    {
      "x": 7,
      "y": 5,
      "z": -8,
      "name": "Wood_Beech_Trunk",
      "support": 15,
      "rotation": 5
    },
    {
      "x": 7,
      "y": 6,
      "z": -8,
      "name": "*Wood_Village_Wall_Full_State_Definitions_Bottom"
    },
    {
      "x": 7,
      "y": 7,
      "z": -8,
      "name": "*Wood_Village_Wall_Full_State_Definitions_Top"
    },
    {
      "x": 7,
      "y": 8,
      "z": -8,
      "name": "Cloth_Block_Wool_Black"
    },
    {
      "x": 7,
      "y": 12,
      "z": -8,
      "name": "Cloth_Block_Wool_Black"
    },
    {
      "x": 7,
      "y": 1,
      "z": -7,
      "name": "Wood_Softwood_Planks"
    },
    {
      "x": 7,
      "y": 2,
      "z": -7,
      "name": "Wood_Deadwood_Planks"
    },
    {
      "x": 7,
      "y": 3,
      "z": -7,
      "name": "Wood_Deadwood_Stairs",
      "rotation": 11
    },
    {
      "x": 7,
      "y": 4,
      "z": -7,
      "name": "Wood_Deadwood_Planks_Half"
    },
    {
      "x": 7,
      "y": 13,
      "z": -7,
      "name": "Cloth_Block_Wool_Black"
    },
    {
      "x": 7,
      "y": 1,
      "z": -6,
      "name": "Wood_Softwood_Planks"
    },
    {
      "x": 7,
      "y": 5,
      "z": -6,
      "name": "Furniture_Tavern_Chandelier",
      "filler": 32767
    },
    {
      "x": 7,
      "y": 6,
      "z": -6,
      "name": "Furniture_Tavern_Chandelier",
      "filler": 1023
    },
    {
      "x": 7,
      "y": 13,
      "z": -6,
      "name": "Cloth_Block_Wool_Black"
    },
    {
      "x": 7,
      "y": 1,
      "z": -5,
      "name": "Wood_Softwood_Planks"
    },
    {
      "x": 7,
      "y": 2,
      "z": -5,
      "name": "Furniture_Human_Ruins_Desk",
      "filler": 31
    },
    {
      "x": 7,
      "y": 5,
      "z": -5,
      "name": "Furniture_Tavern_Chandelier",
      "filler": 31775
    },
    {
      "x": 7,
      "y": 6,
      "z": -5,
      "name": "Furniture_Tavern_Chandelier",
      "filler": 31
    },
    {
      "x": 7,
      "y": 13,
      "z": -5,
      "name": "Cloth_Block_Wool_Black"
    },
    {
      "x": 7,
      "y": 15,
      "z": -5,
      "name": "Cloth_Block_Wool_White"
    },
    {
      "x": 7,
      "y": 1,
      "z": -4,
      "name": "Wood_Softwood_Planks"
    },
    {
      "x": 7,
      "y": 5,
      "z": -4,
      "name": "Furniture_Tavern_Chandelier",
      "filler": 31807
    },
    {
      "x": 7,
      "y": 6,
      "z": -4,
      "name": "Furniture_Tavern_Chandelier",
      "filler": 63
    },
    {
      "x": 7,
      "y": 13,
      "z": -4,
      "name": "Cloth_Block_Wool_Black"
    },
    {
      "x": 7,
      "y": 1,
      "z": -3,
      "name": "Wood_Softwood_Planks"
    },
    {
      "x": 7,
      "y": 13,
      "z": -3,
      "name": "Cloth_Block_Wool_Black"
    },
    {
      "x": 7,
      "y": 1,
      "z": -2,
      "name": "Rock_Stone_Cobble"
    },
    {
      "x": 7,
      "y": 2,
      "z": -2,
      "name": "Rock_Stone_Brick"
    },
    {
      "x": 7,
      "y": 3,
      "z": -2,
      "name": "*Wood_Village_Wall_Full_State_Definitions_Bottom"
    },
    {
      "x": 7,
      "y": 4,
      "z": -2,
      "name": "*Wood_Village_Wall_Full_State_Definitions_Top"
    },
    {
      "x": 7,
      "y": 5,
      "z": -2,
      "name": "Wood_Beech_Trunk",
      "support": 15,
      "rotation": 5
    },
    {
      "x": 7,
      "y": 6,
      "z": -2,
      "name": "*Wood_Village_Wall_Full_State_Definitions_Bottom"
    },
    {
      "x": 7,
      "y": 7,
      "z": -2,
      "name": "*Wood_Village_Wall_Full_State_Definitions_Top"
    },
    {
      "x": 7,
      "y": 8,
      "z": -2,
      "name": "Cloth_Block_Wool_Black"
    },
    {
      "x": 7,
      "y": 12,
      "z": -2,
      "name": "Cloth_Block_Wool_Black"
    },
    {
      "x": 7,
      "y": 1,
      "z": -1,
      "name": "Rock_Stone_Cobble_Mossy"
    },
    {
      "x": 7,
      "y": 7,
      "z": -1,
      "name": "Wood_Softwood_Planks_Half",
      "rotation": 8
    },
    {
      "x": 7,
      "y": 8,
      "z": -1,
      "name": "Cloth_Block_Wool_Yellow_Light"
    },
    {
      "x": 7,
      "y": 9,
      "z": -1,
      "name": "Cloth_Block_Wool_Yellow_Light"
    },
    {
      "x": 7,
      "y": 10,
      "z": -1,
      "name": "Cloth_Block_Wool_Black"
    },
    {
      "x": 7,
      "y": 11,
      "z": -1,
      "name": "Cloth_Block_Wool_Yellow_Light"
    },
    {
      "x": 8,
      "y": 1,
      "z": -9,
      "name": "Rock_Stone_Cobble_Mossy"
    },
    {
      "x": 8,
      "y": 5,
      "z": -9,
      "name": "Wood_Beech_Branch_Short",
      "support": 15,
      "rotation": 2
    },
    {
      "x": 8,
      "y": 7,
      "z": -9,
      "name": "Wood_Softwood_Planks_Half",
      "rotation": 8
    },
    {
      "x": 8,
      "y": 8,
      "z": -9,
      "name": "Wood_Softwood_Roof_Flat"
    },
    {
      "x": 8,
      "y": 9,
      "z": -9,
      "name": "Cloth_Block_Wool_Black"
    },
    {
      "x": 8,
      "y": 10,
      "z": -9,
      "name": "Cloth_Block_Wool_Black"
    },
    {
      "x": 8,
      "y": 11,
      "z": -9,
      "name": "Cloth_Block_Wool_Black"
    },
    {
      "x": 8,
      "y": 1,
      "z": -8,
      "name": "Rock_Stone_Cobble"
    },
    {
      "x": 8,
      "y": 2,
      "z": -8,
      "name": "Wood_Beech_Trunk",
      "support": 15
    },
    {
      "x": 8,
      "y": 3,
      "z": -8,
      "name": "Wood_Beech_Trunk",
      "support": 15
    },
    {
      "x": 8,
      "y": 4,
      "z": -8,
      "name": "Wood_Beech_Trunk",
      "support": 15
    },
    {
      "x": 8,
      "y": 5,
      "z": -8,
      "name": "Wood_Beech_Trunk",
      "support": 15
    },
    {
      "x": 8,
      "y": 6,
      "z": -8,
      "name": "Wood_Beech_Trunk",
      "support": 15
    },
    {
      "x": 8,
      "y": 7,
      "z": -8,
      "name": "Wood_Beech_Trunk",
      "support": 15
    },
    {
      "x": 8,
      "y": 8,
      "z": -8,
      "name": "Cloth_Block_Wool_Black"
    },
    {
      "x": 8,
      "y": 12,
      "z": -8,
      "name": "Cloth_Block_Wool_Black"
    },
    {
      "x": 8,
      "y": 1,
      "z": -7,
      "name": "Wood_Softwood_Planks"
    },
    {
      "x": 8,
      "y": 2,
      "z": -7,
      "name": "Wood_Deadwood_Planks"
    },
    {
      "x": 8,
      "y": 3,
      "z": -7,
      "name": "Aetherhaven_Management_Block",
      "components": {
        "Components": {
          "AetherhavenManagementBlock": {
            "PlotId": "",
            "TownId": ""
          },
          "PlacedByInteraction": {
            "WhoPlacedUuid": {
              "$binary": "v7RyWIT/TYKnXA2XcxdQtw==",
              "$type": "04"
            }
          }
        }
      }
    },
    {
      "x": 8,
      "y": 4,
      "z": -7,
      "name": "Wood_Deadwood_Planks_Half"
    },
    {
      "x": 8,
      "y": 13,
      "z": -7,
      "name": "Cloth_Block_Wool_Black"
    },
    {
      "x": 8,
      "y": 1,
      "z": -6,
      "name": "Wood_Softwood_Planks"
    },
    {
      "x": 8,
      "y": 5,
      "z": -6,
      "name": "Furniture_Tavern_Chandelier",
      "filler": 32736
    },
    {
      "x": 8,
      "y": 6,
      "z": -6,
      "name": "Furniture_Tavern_Chandelier",
      "filler": 992
    },
    {
      "x": 8,
      "y": 13,
      "z": -6,
      "name": "Cloth_Block_Wool_Black"
    },
    {
      "x": 8,
      "y": 1,
      "z": -5,
      "name": "Wood_Softwood_Planks"
    },
    {
      "x": 8,
      "y": 2,
      "z": -5,
      "name": "Furniture_Human_Ruins_Desk"
    },
    {
      "x": 8,
      "y": 5,
      "z": -5,
      "name": "Furniture_Tavern_Chandelier",
      "filler": 31744
    },
    {
      "x": 8,
      "y": 6,
      "z": -5,
      "name": "Furniture_Tavern_Chandelier"
    },
    {
      "x": 8,
      "y": 7,
      "z": -5,
      "name": "Deco_Iron_Chain_Small"
    },
    {
      "x": 8,
      "y": 8,
      "z": -5,
      "name": "Deco_Iron_Chain_Small"
    },
    {
      "x": 8,
      "y": 9,
      "z": -5,
      "name": "Deco_Iron_Chain_Small"
    },
    {
      "x": 8,
      "y": 10,
      "z": -5,
      "name": "Deco_Iron_Chain_Small"
    },
    {
      "x": 8,
      "y": 11,
      "z": -5,
      "name": "Deco_Iron_Chain_Small"
    },
    {
      "x": 8,
      "y": 12,
      "z": -5,
      "name": "Deco_Iron_Chain_Small"
    },
    {
      "x": 8,
      "y": 13,
      "z": -5,
      "name": "Cloth_Block_Wool_White"
    },
    {
      "x": 8,
      "y": 14,
      "z": -5,
      "name": "Cloth_Block_Wool_White"
    },
    {
      "x": 8,
      "y": 1,
      "z": -4,
      "name": "Wood_Softwood_Planks"
    },
    {
      "x": 8,
      "y": 5,
      "z": -4,
      "name": "Furniture_Tavern_Chandelier",
      "filler": 31776
    },
    {
      "x": 8,
      "y": 6,
      "z": -4,
      "name": "Furniture_Tavern_Chandelier",
      "filler": 32
    },
    {
      "x": 8,
      "y": 13,
      "z": -4,
      "name": "Cloth_Block_Wool_Black"
    },
    {
      "x": 8,
      "y": 1,
      "z": -3,
      "name": "Wood_Softwood_Planks"
    },
    {
      "x": 8,
      "y": 13,
      "z": -3,
      "name": "Cloth_Block_Wool_Black"
    },
    {
      "x": 8,
      "y": 1,
      "z": -2,
      "name": "Wood_Softwood_Planks"
    },
    {
      "x": 8,
      "y": 2,
      "z": -2,
      "name": "*Furniture_Village_Door_State_Definitions_CloseDoorIn"
    },
    {
      "x": 8,
      "y": 3,
      "z": -2,
      "name": "*Furniture_Village_Door_State_Definitions_CloseDoorIn",
      "filler": 1024
    },
    {
      "x": 8,
      "y": 4,
      "z": -2,
      "name": "Wood_Village_Wall_Full"
    },
    {
      "x": 8,
      "y": 5,
      "z": -2,
      "name": "Wood_Beech_Trunk",
      "support": 15,
      "rotation": 5
    },
    {
      "x": 8,
      "y": 6,
      "z": -2,
      "name": "Wood_Beech_Trunk",
      "support": 15
    },
    {
      "x": 8,
      "y": 7,
      "z": -2,
      "name": "Wood_Beech_Trunk",
      "support": 15
    },
    {
      "x": 8,
      "y": 8,
      "z": -2,
      "name": "Cloth_Block_Wool_Black"
    },
    {
      "x": 8,
      "y": 12,
      "z": -2,
      "name": "Cloth_Block_Wool_Black"
    },
    {
      "x": 8,
      "y": 1,
      "z": -1,
      "name": "Rock_Stone_Cobble"
    },
    {
      "x": 8,
      "y": 5,
      "z": -1,
      "name": "Wood_Beech_Branch_Short",
      "support": 15
    },
    {
      "x": 8,
      "y": 7,
      "z": -1,
      "name": "Wood_Softwood_Planks_Half",
      "rotation": 8
    },
    {
      "x": 8,
      "y": 8,
      "z": -1,
      "name": "Cloth_Block_Wool_Yellow_Light"
    },
    {
      "x": 8,
      "y": 9,
      "z": -1,
      "name": "Cloth_Block_Wool_Black"
    },
    {
      "x": 8,
      "y": 10,
      "z": -1,
      "name": "Cloth_Block_Wool_Yellow_Light"
    },
    {
      "x": 8,
      "y": 11,
      "z": -1,
      "name": "Cloth_Block_Wool_Yellow_Light"
    },
    {
      "x": 9,
      "y": 1,
      "z": -9,
      "name": "Rock_Stone_Cobble"
    },
    {
      "x": 9,
      "y": 6,
      "z": -9,
      "name": "Plant_Vine_Wall",
      "support": 15,
      "rotation": 2
    },
    {
      "x": 9,
      "y": 7,
      "z": -9,
      "name": "Wood_Softwood_Planks_Half",
      "rotation": 8
    },
    {
      "x": 9,
      "y": 8,
      "z": -9,
      "name": "Wood_Softwood_Roof_Flat"
    },
    {
      "x": 9,
      "y": 9,
      "z": -9,
      "name": "Cloth_Block_Wool_Black"
    },
    {
      "x": 9,
      "y": 10,
      "z": -9,
      "name": "Cloth_Block_Wool_Black"
    },
    {
      "x": 9,
      "y": 11,
      "z": -9,
      "name": "Cloth_Block_Wool_Black"
    },
    {
      "x": 9,
      "y": 1,
      "z": -8,
      "name": "Rock_Stone_Cobble_Mossy"
    },
    {
      "x": 9,
      "y": 2,
      "z": -8,
      "name": "Rock_Stone_Brick"
    },
    {
      "x": 9,
      "y": 3,
      "z": -8,
      "name": "*Wood_Village_Wall_Full_State_Definitions_Bottom"
    },
    {
      "x": 9,
      "y": 4,
      "z": -8,
      "name": "*Wood_Village_Wall_Full_State_Definitions_Top"
    },
    {
      "x": 9,
      "y": 5,
      "z": -8,
      "name": "Wood_Beech_Trunk",
      "support": 15,
      "rotation": 5
    },
    {
      "x": 9,
      "y": 6,
      "z": -8,
      "name": "*Wood_Village_Wall_Full_State_Definitions_Bottom"
    },
    {
      "x": 9,
      "y": 7,
      "z": -8,
      "name": "*Wood_Village_Wall_Full_State_Definitions_Top"
    },
    {
      "x": 9,
      "y": 8,
      "z": -8,
      "name": "Cloth_Block_Wool_Black"
    },
    {
      "x": 9,
      "y": 12,
      "z": -8,
      "name": "Cloth_Block_Wool_Black"
    },
    {
      "x": 9,
      "y": 1,
      "z": -7,
      "name": "Wood_Softwood_Planks"
    },
    {
      "x": 9,
      "y": 2,
      "z": -7,
      "name": "Wood_Deadwood_Planks"
    },
    {
      "x": 9,
      "y": 3,
      "z": -7,
      "name": "Wood_Deadwood_Stairs",
      "rotation": 9
    },
    {
      "x": 9,
      "y": 4,
      "z": -7,
      "name": "Wood_Deadwood_Planks_Half"
    },
    {
      "x": 9,
      "y": 13,
      "z": -7,
      "name": "Cloth_Block_Wool_Black"
    },
    {
      "x": 9,
      "y": 1,
      "z": -6,
      "name": "Wood_Softwood_Planks"
    },
    {
      "x": 9,
      "y": 5,
      "z": -6,
      "name": "Furniture_Tavern_Chandelier",
      "filler": 32737
    },
    {
      "x": 9,
      "y": 6,
      "z": -6,
      "name": "Furniture_Tavern_Chandelier",
      "filler": 993
    },
    {
      "x": 9,
      "y": 13,
      "z": -6,
      "name": "Cloth_Block_Wool_Black"
    },
    {
      "x": 9,
      "y": 1,
      "z": -5,
      "name": "Wood_Softwood_Planks"
    },
    {
      "x": 9,
      "y": 2,
      "z": -5,
      "name": "Wood_Deadwood_Planks"
    },
    {
      "x": 9,
      "y": 3,
      "z": -5,
      "name": "Aetherhaven_Shop_Spot",
      "components": {
        "Components": {
          "AetherhavenShopSpotBlock": {
            "SpotId": "143914cc-f115-4f9f-8afb-357263a90814",
            "TownId": "d87b9d18-a6de-42a7-9697-90f4c2aa0d9f",
            "PlotId": "00000000-0000-0000-0000-000000000000",
            "PlayerControlled": false,
            "LootTableId": "pyro_berry",
            "Configured": true
          },
          "PlacedByInteraction": {
            "WhoPlacedUuid": {
              "$binary": "v7RyWIT/TYKnXA2XcxdQtw==",
              "$type": "04"
            }
          }
        }
      }
    },
    {
      "x": 9,
      "y": 5,
      "z": -5,
      "name": "Furniture_Tavern_Chandelier",
      "filler": 31745
    },
    {
      "x": 9,
      "y": 6,
      "z": -5,
      "name": "Furniture_Tavern_Chandelier",
      "filler": 1
    },
    {
      "x": 9,
      "y": 13,
      "z": -5,
      "name": "Cloth_Block_Wool_Black"
    },
    {
      "x": 9,
      "y": 1,
      "z": -4,
      "name": "Wood_Softwood_Planks"
    },
    {
      "x": 9,
      "y": 5,
      "z": -4,
      "name": "Furniture_Tavern_Chandelier",
      "filler": 31777
    },
    {
      "x": 9,
      "y": 6,
      "z": -4,
      "name": "Furniture_Tavern_Chandelier",
      "filler": 33
    },
    {
      "x": 9,
      "y": 13,
      "z": -4,
      "name": "Cloth_Block_Wool_Black"
    },
    {
      "x": 9,
      "y": 1,
      "z": -3,
      "name": "Wood_Softwood_Planks"
    },
    {
      "x": 9,
      "y": 13,
      "z": -3,
      "name": "Cloth_Block_Wool_Black"
    },
    {
      "x": 9,
      "y": 1,
      "z": -2,
      "name": "Rock_Stone_Cobble"
    },
    {
      "x": 9,
      "y": 2,
      "z": -2,
      "name": "Rock_Stone_Brick"
    },
    {
      "x": 9,
      "y": 3,
      "z": -2,
      "name": "*Wood_Village_Wall_Full_State_Definitions_Bottom"
    },
    {
      "x": 9,
      "y": 4,
      "z": -2,
      "name": "*Wood_Village_Wall_Full_State_Definitions_Top"
    },
    {
      "x": 9,
      "y": 5,
      "z": -2,
      "name": "Wood_Beech_Trunk",
      "support": 15,
      "rotation": 5
    },
    {
      "x": 9,
      "y": 6,
      "z": -2,
      "name": "*Wood_Village_Wall_Full_State_Definitions_Bottom"
    },
    {
      "x": 9,
      "y": 7,
      "z": -2,
      "name": "*Wood_Village_Wall_Full_State_Definitions_Top"
    },
    {
      "x": 9,
      "y": 8,
      "z": -2,
      "name": "Cloth_Block_Wool_Black"
    },
    {
      "x": 9,
      "y": 12,
      "z": -2,
      "name": "Cloth_Block_Wool_Black"
    },
    {
      "x": 9,
      "y": 1,
      "z": -1,
      "name": "Rock_Stone_Cobble"
    },
    {
      "x": 9,
      "y": 5,
      "z": -1,
      "name": "Plant_Vine_Wall",
      "support": 15
    },
    {
      "x": 9,
      "y": 7,
      "z": -1,
      "name": "Wood_Softwood_Planks_Half",
      "rotation": 8
    },
    {
      "x": 9,
      "y": 8,
      "z": -1,
      "name": "Cloth_Block_Wool_Yellow_Light"
    },
    {
      "x": 9,
      "y": 9,
      "z": -1,
      "name": "Cloth_Block_Wool_Yellow_Light"
    },
    {
      "x": 9,
      "y": 10,
      "z": -1,
      "name": "Cloth_Block_Wool_Black"
    },
    {
      "x": 9,
      "y": 11,
      "z": -1,
      "name": "Cloth_Block_Wool_Yellow_Light"
    },
    {
      "x": 10,
      "y": 1,
      "z": -9,
      "name": "Rock_Stone_Cobble"
    },
    {
      "x": 10,
      "y": 5,
      "z": -9,
      "name": "Wood_Beech_Branch_Short",
      "support": 15,
      "rotation": 2
    },
    {
      "x": 10,
      "y": 7,
      "z": -9,
      "name": "Wood_Softwood_Planks_Half",
      "rotation": 8
    },
    {
      "x": 10,
      "y": 8,
      "z": -9,
      "name": "Wood_Softwood_Roof_Flat"
    },
    {
      "x": 10,
      "y": 1,
      "z": -8,
      "name": "Rock_Stone_Cobble_Mossy"
    },
    {
      "x": 10,
      "y": 2,
      "z": -8,
      "name": "Rock_Stone_Brick"
    },
    {
      "x": 10,
      "y": 3,
      "z": -8,
      "name": "*Wood_Village_Wall_Full_State_Definitions_Bottom"
    },
    {
      "x": 10,
      "y": 4,
      "z": -8,
      "name": "*Wood_Village_Wall_Full_State_Definitions_Top"
    },
    {
      "x": 10,
      "y": 5,
      "z": -8,
      "name": "Wood_Beech_Trunk",
      "support": 15,
      "rotation": 5
    },
    {
      "x": 10,
      "y": 6,
      "z": -8,
      "name": "Furniture_Village_Window"
    },
    {
      "x": 10,
      "y": 7,
      "z": -8,
      "name": "Wood_Village_Wall_Full"
    },
    {
      "x": 10,
      "y": 8,
      "z": -8,
      "name": "Wood_Softwood_Roof_Flat"
    },
    {
      "x": 10,
      "y": 9,
      "z": -8,
      "name": "Cloth_Block_Wool_Black"
    },
    {
      "x": 10,
      "y": 10,
      "z": -8,
      "name": "Cloth_Block_Wool_Black"
    },
    {
      "x": 10,
      "y": 11,
      "z": -8,
      "name": "Cloth_Block_Wool_Black"
    },
    {
      "x": 10,
      "y": 1,
      "z": -7,
      "name": "Wood_Softwood_Planks"
    },
    {
      "x": 10,
      "y": 2,
      "z": -7,
      "name": "Wood_Deadwood_Planks"
    },
    {
      "x": 10,
      "y": 3,
      "z": -7,
      "name": "Wood_Deadwood_Stairs",
      "rotation": 1
    },
    {
      "x": 10,
      "y": 7,
      "z": -7,
      "name": "Wood_Softwood_Planks_Half",
      "rotation": 8
    },
    {
      "x": 10,
      "y": 8,
      "z": -7,
      "name": "Cloth_Block_Wool_Black"
    },
    {
      "x": 10,
      "y": 12,
      "z": -7,
      "name": "Cloth_Block_Wool_Black"
    },
    {
      "x": 10,
      "y": 1,
      "z": -6,
      "name": "Wood_Softwood_Planks"
    },
    {
      "x": 10,
      "y": 13,
      "z": -6,
      "name": "Cloth_Block_Wool_Black"
    },
    {
      "x": 10,
      "y": 1,
      "z": -5,
      "name": "Wood_Softwood_Planks"
    },
    {
      "x": 10,
      "y": 2,
      "z": -5,
      "name": "Wood_Deadwood_Planks"
    },
    {
      "x": 10,
      "y": 3,
      "z": -5,
      "name": "Aetherhaven_Shop_Spot",
      "components": {
        "Components": {
          "AetherhavenShopSpotBlock": {
            "SpotId": "1ad41ad1-4dcd-4b6e-b2ee-2cfb87fb7142",
            "TownId": "d87b9d18-a6de-42a7-9697-90f4c2aa0d9f",
            "PlotId": "00000000-0000-0000-0000-000000000000",
            "PlayerControlled": false,
            "LootTableId": "pyro_poison",
            "Configured": true
          },
          "PlacedByInteraction": {
            "WhoPlacedUuid": {
              "$binary": "v7RyWIT/TYKnXA2XcxdQtw==",
              "$type": "04"
            }
          }
        }
      }
    },
    {
      "x": 10,
      "y": 13,
      "z": -5,
      "name": "Cloth_Block_Wool_Black"
    },
    {
      "x": 10,
      "y": 1,
      "z": -4,
      "name": "Wood_Softwood_Planks"
    },
    {
      "x": 10,
      "y": 13,
      "z": -4,
      "name": "Cloth_Block_Wool_Black"
    },
    {
      "x": 10,
      "y": 1,
      "z": -3,
      "name": "Wood_Softwood_Planks"
    },
    {
      "x": 10,
      "y": 7,
      "z": -3,
      "name": "Wood_Softwood_Planks_Half",
      "rotation": 8
    },
    {
      "x": 10,
      "y": 8,
      "z": -3,
      "name": "Cloth_Block_Wool_Black"
    },
    {
      "x": 10,
      "y": 12,
      "z": -3,
      "name": "Cloth_Block_Wool_Black"
    },
    {
      "x": 10,
      "y": 1,
      "z": -2,
      "name": "Rock_Stone_Cobble"
    },
    {
      "x": 10,
      "y": 2,
      "z": -2,
      "name": "Rock_Stone_Brick"
    },
    {
      "x": 10,
      "y": 3,
      "z": -2,
      "name": "*Wood_Village_Wall_Full_State_Definitions_Bottom"
    },
    {
      "x": 10,
      "y": 4,
      "z": -2,
      "name": "*Wood_Village_Wall_Full_State_Definitions_Top"
    },
    {
      "x": 10,
      "y": 5,
      "z": -2,
      "name": "Wood_Beech_Trunk",
      "support": 15,
      "rotation": 5
    },
    {
      "x": 10,
      "y": 6,
      "z": -2,
      "name": "Furniture_Village_Window"
    },
    {
      "x": 10,
      "y": 7,
      "z": -2,
      "name": "Wood_Village_Wall_Full"
    },
    {
      "x": 10,
      "y": 8,
      "z": -2,
      "name": "Wood_Softwood_Roof_Flat"
    },
    {
      "x": 10,
      "y": 9,
      "z": -2,
      "name": "Cloth_Block_Wool_Black"
    },
    {
      "x": 10,
      "y": 10,
      "z": -2,
      "name": "Cloth_Block_Wool_Yellow_Light"
    },
    {
      "x": 10,
      "y": 11,
      "z": -2,
      "name": "Cloth_Block_Wool_Black"
    },
    {
      "x": 10,
      "y": 1,
      "z": -1,
      "name": "Rock_Stone_Cobble"
    },
    {
      "x": 10,
      "y": 5,
      "z": -1,
      "name": "Wood_Beech_Branch_Short",
      "support": 15
    },
    {
      "x": 10,
      "y": 7,
      "z": -1,
      "name": "Wood_Softwood_Planks_Half",
      "rotation": 8
    },
    {
      "x": 10,
      "y": 8,
      "z": -1,
      "name": "Wood_Softwood_Roof_Flat"
    },
    {
      "x": 11,
      "y": 1,
      "z": -9,
      "name": "Rock_Stone_Cobble"
    },
    {
      "x": 11,
      "y": 7,
      "z": -9,
      "name": "Wood_Softwood_Planks_Half",
      "rotation": 8
    },
    {
      "x": 11,
      "y": 8,
      "z": -9,
      "name": "Wood_Softwood_Roof_Flat"
    },
    {
      "x": 11,
      "y": 1,
      "z": -8,
      "name": "Rock_Stone_Cobble"
    },
    {
      "x": 11,
      "y": 2,
      "z": -8,
      "name": "Rock_Stone_Brick"
    },
    {
      "x": 11,
      "y": 3,
      "z": -8,
      "name": "Furniture_Village_Window"
    },
    {
      "x": 11,
      "y": 4,
      "z": -8,
      "name": "Furniture_Village_Window"
    },
    {
      "x": 11,
      "y": 5,
      "z": -8,
      "name": "Wood_Beech_Trunk",
      "support": 15,
      "rotation": 5
    },
    {
      "x": 11,
      "y": 6,
      "z": -8,
      "name": "Furniture_Village_Window"
    },
    {
      "x": 11,
      "y": 7,
      "z": -8,
      "name": "Wood_Village_Wall_Full"
    },
    {
      "x": 11,
      "y": 8,
      "z": -8,
      "name": "Wood_Softwood_Roof_Flat"
    },
    {
      "x": 11,
      "y": 1,
      "z": -7,
      "name": "Wood_Softwood_Planks"
    },
    {
      "x": 11,
      "y": 7,
      "z": -7,
      "name": "Wood_Softwood_Planks_Half",
      "rotation": 8
    },
    {
      "x": 11,
      "y": 8,
      "z": -7,
      "name": "Wood_Softwood_Roof_Flat"
    },
    {
      "x": 11,
      "y": 9,
      "z": -7,
      "name": "Cloth_Block_Wool_Black"
    },
    {
      "x": 11,
      "y": 10,
      "z": -7,
      "name": "Cloth_Block_Wool_Black"
    },
    {
      "x": 11,
      "y": 11,
      "z": -7,
      "name": "Cloth_Block_Wool_Black"
    },
    {
      "x": 11,
      "y": 1,
      "z": -6,
      "name": "Wood_Softwood_Planks"
    },
    {
      "x": 11,
      "y": 7,
      "z": -6,
      "name": "Wood_Softwood_Planks_Half",
      "rotation": 8
    },
    {
      "x": 11,
      "y": 8,
      "z": -6,
      "name": "Cloth_Block_Wool_Black"
    },
    {
      "x": 11,
      "y": 12,
      "z": -6,
      "name": "Cloth_Block_Wool_Black"
    },
    {
      "x": 11,
      "y": 1,
      "z": -5,
      "name": "Wood_Softwood_Planks"
    },
    {
      "x": 11,
      "y": 2,
      "z": -5,
      "name": "Wood_Deadwood_Planks"
    },
    {
      "x": 11,
      "y": 3,
      "z": -5,
      "name": "Aetherhaven_Shop_Spot",
      "components": {
        "Components": {
          "AetherhavenShopSpotBlock": {
            "SpotId": "b70f6a0e-7aae-4933-bbb9-266ea859d2c7",
            "TownId": "d87b9d18-a6de-42a7-9697-90f4c2aa0d9f",
            "PlotId": "00000000-0000-0000-0000-000000000000",
            "PlayerControlled": false,
            "LootTableId": "pyro_stun",
            "Configured": true
          },
          "PlacedByInteraction": {
            "WhoPlacedUuid": {
              "$binary": "v7RyWIT/TYKnXA2XcxdQtw==",
              "$type": "04"
            }
          }
        }
      }
    },
    {
      "x": 11,
      "y": 7,
      "z": -5,
      "name": "Wood_Softwood_Planks_Half",
      "rotation": 8
    },
    {
      "x": 11,
      "y": 8,
      "z": -5,
      "name": "Cloth_Block_Wool_Black"
    },
    {
      "x": 11,
      "y": 12,
      "z": -5,
      "name": "Cloth_Block_Wool_Black"
    },
    {
      "x": 11,
      "y": 1,
      "z": -4,
      "name": "Wood_Softwood_Planks"
    },
    {
      "x": 11,
      "y": 7,
      "z": -4,
      "name": "Wood_Softwood_Planks_Half",
      "rotation": 8
    },
    {
      "x": 11,
      "y": 8,
      "z": -4,
      "name": "Cloth_Block_Wool_Black"
    },
    {
      "x": 11,
      "y": 12,
      "z": -4,
      "name": "Cloth_Block_Wool_Black"
    },
    {
      "x": 11,
      "y": 1,
      "z": -3,
      "name": "Wood_Softwood_Planks"
    },
    {
      "x": 11,
      "y": 7,
      "z": -3,
      "name": "Wood_Softwood_Planks_Half",
      "rotation": 8
    },
    {
      "x": 11,
      "y": 8,
      "z": -3,
      "name": "Wood_Softwood_Roof_Flat"
    },
    {
      "x": 11,
      "y": 9,
      "z": -3,
      "name": "Cloth_Block_Wool_Black"
    },
    {
      "x": 11,
      "y": 10,
      "z": -3,
      "name": "Cloth_Block_Wool_Black"
    },
    {
      "x": 11,
      "y": 11,
      "z": -3,
      "name": "Cloth_Block_Wool_Black"
    },
    {
      "x": 11,
      "y": 1,
      "z": -2,
      "name": "Rock_Stone_Cobble_Mossy"
    },
    {
      "x": 11,
      "y": 2,
      "z": -2,
      "name": "Rock_Stone_Brick_Mossy"
    },
    {
      "x": 11,
      "y": 3,
      "z": -2,
      "name": "Furniture_Village_Window"
    },
    {
      "x": 11,
      "y": 4,
      "z": -2,
      "name": "Furniture_Village_Window"
    },
    {
      "x": 11,
      "y": 5,
      "z": -2,
      "name": "Wood_Beech_Trunk",
      "support": 15,
      "rotation": 5
    },
    {
      "x": 11,
      "y": 6,
      "z": -2,
      "name": "Furniture_Village_Window"
    },
    {
      "x": 11,
      "y": 7,
      "z": -2,
      "name": "Wood_Village_Wall_Full"
    },
    {
      "x": 11,
      "y": 8,
      "z": -2,
      "name": "Wood_Softwood_Roof_Flat"
    },
    {
      "x": 11,
      "y": 1,
      "z": -1,
      "name": "Rock_Stone_Cobble_Mossy"
    },
    {
      "x": 11,
      "y": 7,
      "z": -1,
      "name": "Wood_Softwood_Planks_Half",
      "rotation": 8
    },
    {
      "x": 11,
      "y": 8,
      "z": -1,
      "name": "Wood_Softwood_Roof_Flat"
    },
    {
      "x": 12,
      "y": 1,
      "z": -9,
      "name": "Rock_Stone_Cobble"
    },
    {
      "x": 12,
      "y": 5,
      "z": -9,
      "name": "Wood_Beech_Branch_Short",
      "support": 15,
      "rotation": 2
    },
    {
      "x": 12,
      "y": 7,
      "z": -9,
      "name": "Wood_Softwood_Stairs",
      "rotation": 9
    },
    {
      "x": 12,
      "y": 8,
      "z": -9,
      "name": "Wood_Softwood_Roof_Flat"
    },
    {
      "x": 12,
      "y": 1,
      "z": -8,
      "name": "Rock_Stone_Cobble"
    },
    {
      "x": 12,
      "y": 2,
      "z": -8,
      "name": "Rock_Stone_Brick_Mossy"
    },
    {
      "x": 12,
      "y": 3,
      "z": -8,
      "name": "Furniture_Village_Window"
    },
    {
      "x": 12,
      "y": 4,
      "z": -8,
      "name": "Furniture_Village_Window"
    },
    {
      "x": 12,
      "y": 5,
      "z": -8,
      "name": "Wood_Beech_Trunk",
      "support": 15,
      "rotation": 5
    },
    {
      "x": 12,
      "y": 6,
      "z": -8,
      "name": "*Wood_Village_Wall_Full_State_Definitions_Bottom"
    },
    {
      "x": 12,
      "y": 7,
      "z": -8,
      "name": "*Wood_Village_Wall_Full_State_Definitions_Top"
    },
    {
      "x": 12,
      "y": 8,
      "z": -8,
      "name": "Wood_Softwood_Roof_Flat"
    },
    {
      "x": 12,
      "y": 1,
      "z": -7,
      "name": "Wood_Softwood_Planks"
    },
    {
      "x": 12,
      "y": 7,
      "z": -7,
      "name": "Wood_Softwood_Stairs",
      "rotation": 9
    },
    {
      "x": 12,
      "y": 8,
      "z": -7,
      "name": "Wood_Softwood_Roof_Flat"
    },
    {
      "x": 12,
      "y": 1,
      "z": -6,
      "name": "Wood_Softwood_Planks"
    },
    {
      "x": 12,
      "y": 7,
      "z": -6,
      "name": "Wood_Softwood_Stairs",
      "rotation": 9
    },
    {
      "x": 12,
      "y": 8,
      "z": -6,
      "name": "Wood_Softwood_Roof_Flat"
    },
    {
      "x": 12,
      "y": 9,
      "z": -6,
      "name": "Cloth_Block_Wool_Black"
    },
    {
      "x": 12,
      "y": 10,
      "z": -6,
      "name": "Cloth_Block_Wool_Black"
    },
    {
      "x": 12,
      "y": 11,
      "z": -6,
      "name": "Cloth_Block_Wool_Black"
    },
    {
      "x": 12,
      "y": 1,
      "z": -5,
      "name": "Wood_Softwood_Planks"
    },
    {
      "x": 12,
      "y": 2,
      "z": -5,
      "name": "Wood_Deadwood_Planks"
    },
    {
      "x": 12,
      "y": 7,
      "z": -5,
      "name": "Wood_Softwood_Stairs",
      "rotation": 9
    },
    {
      "x": 12,
      "y": 8,
      "z": -5,
      "name": "Wood_Softwood_Roof_Flat"
    },
    {
      "x": 12,
      "y": 9,
      "z": -5,
      "name": "Cloth_Block_Wool_Black"
    },
    {
      "x": 12,
      "y": 10,
      "z": -5,
      "name": "Cloth_Block_Wool_Black"
    },
    {
      "x": 12,
      "y": 11,
      "z": -5,
      "name": "Cloth_Block_Wool_Black"
    },
    {
      "x": 12,
      "y": 1,
      "z": -4,
      "name": "Wood_Softwood_Planks"
    },
    {
      "x": 12,
      "y": 7,
      "z": -4,
      "name": "Wood_Softwood_Stairs",
      "rotation": 9
    },
    {
      "x": 12,
      "y": 8,
      "z": -4,
      "name": "Wood_Softwood_Roof_Flat"
    },
    {
      "x": 12,
      "y": 9,
      "z": -4,
      "name": "Cloth_Block_Wool_Black"
    },
    {
      "x": 12,
      "y": 10,
      "z": -4,
      "name": "Cloth_Block_Wool_Black"
    },
    {
      "x": 12,
      "y": 11,
      "z": -4,
      "name": "Cloth_Block_Wool_Black"
    },
    {
      "x": 12,
      "y": 1,
      "z": -3,
      "name": "Wood_Softwood_Planks"
    },
    {
      "x": 12,
      "y": 7,
      "z": -3,
      "name": "Wood_Softwood_Stairs",
      "rotation": 9
    },
    {
      "x": 12,
      "y": 8,
      "z": -3,
      "name": "Wood_Softwood_Roof_Flat"
    },
    {
      "x": 12,
      "y": 1,
      "z": -2,
      "name": "Rock_Stone_Cobble_Mossy"
    },
    {
      "x": 12,
      "y": 2,
      "z": -2,
      "name": "Rock_Stone_Brick"
    },
    {
      "x": 12,
      "y": 3,
      "z": -2,
      "name": "Furniture_Village_Window"
    },
    {
      "x": 12,
      "y": 4,
      "z": -2,
      "name": "Furniture_Village_Window"
    },
    {
      "x": 12,
      "y": 5,
      "z": -2,
      "name": "Wood_Beech_Trunk",
      "support": 15,
      "rotation": 5
    },
    {
      "x": 12,
      "y": 6,
      "z": -2,
      "name": "*Wood_Village_Wall_Full_State_Definitions_Bottom"
    },
    {
      "x": 12,
      "y": 7,
      "z": -2,
      "name": "*Wood_Village_Wall_Full_State_Definitions_Top"
    },
    {
      "x": 12,
      "y": 8,
      "z": -2,
      "name": "Wood_Softwood_Roof_Flat"
    },
    {
      "x": 12,
      "y": 1,
      "z": -1,
      "name": "Rock_Stone_Cobble"
    },
    {
      "x": 12,
      "y": 5,
      "z": -1,
      "name": "Wood_Beech_Branch_Short",
      "support": 15
    },
    {
      "x": 12,
      "y": 7,
      "z": -1,
      "name": "Wood_Softwood_Stairs",
      "rotation": 9
    },
    {
      "x": 12,
      "y": 8,
      "z": -1,
      "name": "Wood_Softwood_Roof_Flat"
    },
    {
      "x": 13,
      "y": 1,
      "z": -9,
      "name": "Rock_Stone_Cobble"
    },
    {
      "x": 13,
      "y": 4,
      "z": -9,
      "name": "Plant_Vine_Wall",
      "support": 15,
      "rotation": 2
    },
    {
      "x": 13,
      "y": 6,
      "z": -9,
      "name": "Wood_Softwood_Stairs",
      "rotation": 9
    },
    {
      "x": 13,
      "y": 7,
      "z": -9,
      "name": "Wood_Softwood_Roof",
      "rotation": 1
    },
    {
      "x": 13,
      "y": 1,
      "z": -8,
      "name": "Rock_Stone_Cobble"
    },
    {
      "x": 13,
      "y": 2,
      "z": -8,
      "name": "Rock_Stone_Brick"
    },
    {
      "x": 13,
      "y": 3,
      "z": -8,
      "name": "*Wood_Village_Wall_Full_State_Definitions_Bottom"
    },
    {
      "x": 13,
      "y": 4,
      "z": -8,
      "name": "*Wood_Village_Wall_Full_State_Definitions_Top"
    },
    {
      "x": 13,
      "y": 5,
      "z": -8,
      "name": "Wood_Beech_Trunk",
      "support": 15,
      "rotation": 5
    },
    {
      "x": 13,
      "y": 6,
      "z": -8,
      "name": "Wood_Village_Wall_Full"
    },
    {
      "x": 13,
      "y": 7,
      "z": -8,
      "name": "Wood_Softwood_Roof",
      "rotation": 1
    },
    {
      "x": 13,
      "y": 1,
      "z": -7,
      "name": "Wood_Softwood_Planks"
    },
    {
      "x": 13,
      "y": 2,
      "z": -7,
      "name": "Furniture_Tavern_Barrel"
    },
    {
      "x": 13,
      "y": 6,
      "z": -7,
      "name": "Wood_Softwood_Stairs",
      "rotation": 9
    },
    {
      "x": 13,
      "y": 7,
      "z": -7,
      "name": "Wood_Softwood_Roof",
      "rotation": 1
    },
    {
      "x": 13,
      "y": 1,
      "z": -6,
      "name": "Wood_Softwood_Planks"
    },
    {
      "x": 13,
      "y": 6,
      "z": -6,
      "name": "Wood_Softwood_Stairs",
      "rotation": 9
    },
    {
      "x": 13,
      "y": 7,
      "z": -6,
      "name": "Wood_Softwood_Roof",
      "rotation": 1
    },
    {
      "x": 13,
      "y": 1,
      "z": -5,
      "name": "Wood_Softwood_Planks"
    },
    {
      "x": 13,
      "y": 2,
      "z": -5,
      "name": "Wood_Deadwood_Planks"
    },
    {
      "x": 13,
      "y": 3,
      "z": -5,
      "name": "Furniture_Human_Ruins_Candle"
    },
    {
      "x": 13,
      "y": 4,
      "z": -5,
      "name": "Furniture_Human_Ruins_Candle",
      "filler": 1024
    },
    {
      "x": 13,
      "y": 6,
      "z": -5,
      "name": "Wood_Softwood_Stairs",
      "rotation": 9
    },
    {
      "x": 13,
      "y": 7,
      "z": -5,
      "name": "Wood_Softwood_Roof",
      "rotation": 1
    },
    {
      "x": 13,
      "y": 1,
      "z": -4,
      "name": "Wood_Softwood_Planks"
    },
    {
      "x": 13,
      "y": 2,
      "z": -4,
      "name": "Furniture_Tavern_Barrel"
    },
    {
      "x": 13,
      "y": 6,
      "z": -4,
      "name": "Wood_Softwood_Stairs",
      "rotation": 9
    },
    {
      "x": 13,
      "y": 7,
      "z": -4,
      "name": "Wood_Softwood_Roof",
      "rotation": 1
    },
    {
      "x": 13,
      "y": 1,
      "z": -3,
      "name": "Wood_Softwood_Planks"
    },
    {
      "x": 13,
      "y": 2,
      "z": -3,
      "name": "Furniture_Village_Crate"
    },
    {
      "x": 13,
      "y": 3,
      "z": -3,
      "name": "Furniture_Village_Crate"
    },
    {
      "x": 13,
      "y": 6,
      "z": -3,
      "name": "Wood_Softwood_Stairs",
      "rotation": 9
    },
    {
      "x": 13,
      "y": 7,
      "z": -3,
      "name": "Wood_Softwood_Roof",
      "rotation": 1
    },
    {
      "x": 13,
      "y": 1,
      "z": -2,
      "name": "Rock_Stone_Cobble_Mossy"
    },
    {
      "x": 13,
      "y": 2,
      "z": -2,
      "name": "Rock_Stone_Brick"
    },
    {
      "x": 13,
      "y": 3,
      "z": -2,
      "name": "*Wood_Village_Wall_Full_State_Definitions_Bottom"
    },
    {
      "x": 13,
      "y": 4,
      "z": -2,
      "name": "*Wood_Village_Wall_Full_State_Definitions_Top"
    },
    {
      "x": 13,
      "y": 5,
      "z": -2,
      "name": "Wood_Beech_Trunk",
      "support": 15,
      "rotation": 5
    },
    {
      "x": 13,
      "y": 6,
      "z": -2,
      "name": "Wood_Village_Wall_Full"
    },
    {
      "x": 13,
      "y": 7,
      "z": -2,
      "name": "Wood_Softwood_Roof",
      "rotation": 1
    },
    {
      "x": 13,
      "y": 1,
      "z": -1,
      "name": "Rock_Stone_Cobble"
    },
    {
      "x": 13,
      "y": 6,
      "z": -1,
      "name": "Wood_Softwood_Stairs",
      "rotation": 9
    },
    {
      "x": 13,
      "y": 7,
      "z": -1,
      "name": "Wood_Softwood_Roof",
      "rotation": 1
    },
    {
      "x": 14,
      "y": 1,
      "z": -9,
      "name": "Rock_Stone_Cobble_Mossy"
    },
    {
      "x": 14,
      "y": 5,
      "z": -9,
      "name": "Wood_Beech_Branch_Corner",
      "support": 15,
      "rotation": 2
    },
    {
      "x": 14,
      "y": 6,
      "z": -9,
      "name": "Wood_Softwood_Roof",
      "rotation": 1
    },
    {
      "x": 14,
      "y": 1,
      "z": -8,
      "name": "Rock_Stone_Cobble"
    },
    {
      "x": 14,
      "y": 2,
      "z": -8,
      "name": "Wood_Beech_Trunk",
      "support": 15
    },
    {
      "x": 14,
      "y": 3,
      "z": -8,
      "name": "Wood_Beech_Trunk",
      "support": 15
    },
    {
      "x": 14,
      "y": 4,
      "z": -8,
      "name": "Wood_Beech_Trunk",
      "support": 15
    },
    {
      "x": 14,
      "y": 5,
      "z": -8,
      "name": "Wood_Beech_Trunk",
      "support": 15
    },
    {
      "x": 14,
      "y": 6,
      "z": -8,
      "name": "Wood_Softwood_Roof",
      "rotation": 1
    },
    {
      "x": 14,
      "y": 1,
      "z": -7,
      "name": "Rock_Stone_Cobble"
    },
    {
      "x": 14,
      "y": 2,
      "z": -7,
      "name": "Rock_Stone_Brick"
    },
    {
      "x": 14,
      "y": 3,
      "z": -7,
      "name": "*Wood_Village_Wall_Full_State_Definitions_Bottom"
    },
    {
      "x": 14,
      "y": 4,
      "z": -7,
      "name": "*Wood_Village_Wall_Full_State_Definitions_Top"
    },
    {
      "x": 14,
      "y": 5,
      "z": -7,
      "name": "Wood_Beech_Trunk",
      "support": 15,
      "rotation": 4
    },
    {
      "x": 14,
      "y": 6,
      "z": -7,
      "name": "Wood_Softwood_Roof",
      "rotation": 1
    },
    {
      "x": 14,
      "y": 1,
      "z": -6,
      "name": "Rock_Stone_Cobble"
    },
    {
      "x": 14,
      "y": 2,
      "z": -6,
      "name": "Rock_Stone_Brick_Mossy"
    },
    {
      "x": 14,
      "y": 3,
      "z": -6,
      "name": "Furniture_Village_Window",
      "rotation": 1
    },
    {
      "x": 14,
      "y": 4,
      "z": -6,
      "name": "Furniture_Village_Window",
      "rotation": 1
    },
    {
      "x": 14,
      "y": 5,
      "z": -6,
      "name": "Wood_Beech_Trunk",
      "support": 15,
      "rotation": 4
    },
    {
      "x": 14,
      "y": 6,
      "z": -6,
      "name": "Wood_Softwood_Roof",
      "rotation": 1
    },
    {
      "x": 14,
      "y": 1,
      "z": -5,
      "name": "Rock_Stone_Cobble"
    },
    {
      "x": 14,
      "y": 2,
      "z": -5,
      "name": "Rock_Stone_Brick"
    },
    {
      "x": 14,
      "y": 3,
      "z": -5,
      "name": "*Wood_Village_Wall_Full_State_Definitions_Bottom"
    },
    {
      "x": 14,
      "y": 4,
      "z": -5,
      "name": "*Wood_Village_Wall_Full_State_Definitions_Top"
    },
    {
      "x": 14,
      "y": 5,
      "z": -5,
      "name": "Wood_Beech_Trunk",
      "support": 15,
      "rotation": 4
    },
    {
      "x": 14,
      "y": 6,
      "z": -5,
      "name": "Wood_Softwood_Roof",
      "rotation": 1
    },
    {
      "x": 14,
      "y": 1,
      "z": -4,
      "name": "Rock_Stone_Cobble"
    },
    {
      "x": 14,
      "y": 2,
      "z": -4,
      "name": "Rock_Stone_Brick"
    },
    {
      "x": 14,
      "y": 3,
      "z": -4,
      "name": "Furniture_Village_Window",
      "rotation": 1
    },
    {
      "x": 14,
      "y": 4,
      "z": -4,
      "name": "Furniture_Village_Window",
      "rotation": 1
    },
    {
      "x": 14,
      "y": 5,
      "z": -4,
      "name": "Wood_Beech_Trunk",
      "support": 15,
      "rotation": 4
    },
    {
      "x": 14,
      "y": 6,
      "z": -4,
      "name": "Wood_Softwood_Roof",
      "rotation": 1
    },
    {
      "x": 14,
      "y": 1,
      "z": -3,
      "name": "Rock_Stone_Cobble"
    },
    {
      "x": 14,
      "y": 2,
      "z": -3,
      "name": "Rock_Stone_Brick"
    },
    {
      "x": 14,
      "y": 3,
      "z": -3,
      "name": "*Wood_Village_Wall_Full_State_Definitions_Bottom"
    },
    {
      "x": 14,
      "y": 4,
      "z": -3,
      "name": "*Wood_Village_Wall_Full_State_Definitions_Top"
    },
    {
      "x": 14,
      "y": 5,
      "z": -3,
      "name": "Wood_Beech_Trunk",
      "support": 15,
      "rotation": 4
    },
    {
      "x": 14,
      "y": 6,
      "z": -3,
      "name": "Wood_Softwood_Roof",
      "rotation": 1
    },
    {
      "x": 14,
      "y": 1,
      "z": -2,
      "name": "Rock_Stone_Cobble"
    },
    {
      "x": 14,
      "y": 2,
      "z": -2,
      "name": "Wood_Beech_Trunk",
      "support": 15
    },
    {
      "x": 14,
      "y": 3,
      "z": -2,
      "name": "Wood_Beech_Trunk",
      "support": 15
    },
    {
      "x": 14,
      "y": 4,
      "z": -2,
      "name": "Wood_Beech_Trunk",
      "support": 15
    },
    {
      "x": 14,
      "y": 5,
      "z": -2,
      "name": "Wood_Beech_Trunk",
      "support": 15
    },
    {
      "x": 14,
      "y": 6,
      "z": -2,
      "name": "Wood_Softwood_Roof",
      "rotation": 1
    },
    {
      "x": 14,
      "y": 1,
      "z": -1,
      "name": "Rock_Stone_Cobble"
    },
    {
      "x": 14,
      "y": 3,
      "z": -1,
      "name": "Plant_Vine_Wall",
      "support": 15
    },
    {
      "x": 14,
      "y": 5,
      "z": -1,
      "name": "Wood_Beech_Branch_Corner",
      "support": 15
    },
    {
      "x": 14,
      "y": 6,
      "z": -1,
      "name": "Wood_Softwood_Roof",
      "rotation": 1
    },
    {
      "x": 15,
      "y": 1,
      "z": -9,
      "name": "Rock_Stone_Cobble_Mossy"
    },
    {
      "x": 15,
      "y": 5,
      "z": -9,
      "name": "Wood_Softwood_Roof_Hollow",
      "rotation": 1
    },
    {
      "x": 15,
      "y": 1,
      "z": -8,
      "name": "Rock_Stone_Cobble_Mossy"
    },
    {
      "x": 15,
      "y": 4,
      "z": -8,
      "name": "Wood_Beech_Branch_Corner",
      "support": 15,
      "rotation": 1
    },
    {
      "x": 15,
      "y": 5,
      "z": -8,
      "name": "Wood_Softwood_Roof",
      "rotation": 1
    },
    {
      "x": 15,
      "y": 1,
      "z": -7,
      "name": "Rock_Stone_Cobble"
    },
    {
      "x": 15,
      "y": 5,
      "z": -7,
      "name": "Wood_Softwood_Roof_Hollow",
      "rotation": 1
    },
    {
      "x": 15,
      "y": 1,
      "z": -6,
      "name": "Rock_Stone_Cobble"
    },
    {
      "x": 15,
      "y": 5,
      "z": -6,
      "name": "Wood_Softwood_Roof_Hollow",
      "rotation": 1
    },
    {
      "x": 15,
      "y": 1,
      "z": -5,
      "name": "Rock_Stone_Cobble"
    },
    {
      "x": 15,
      "y": 4,
      "z": -5,
      "name": "Plant_Vine_Wall",
      "support": 15,
      "rotation": 1
    },
    {
      "x": 15,
      "y": 5,
      "z": -5,
      "name": "Wood_Softwood_Roof_Hollow",
      "rotation": 1
    },
    {
      "x": 15,
      "y": 1,
      "z": -4,
      "name": "Rock_Stone_Cobble"
    },
    {
      "x": 15,
      "y": 5,
      "z": -4,
      "name": "Wood_Softwood_Roof_Hollow",
      "rotation": 1
    },
    {
      "x": 15,
      "y": 1,
      "z": -3,
      "name": "Rock_Stone_Cobble"
    },
    {
      "x": 15,
      "y": 5,
      "z": -3,
      "name": "Wood_Softwood_Roof_Hollow",
      "rotation": 1
    },
    {
      "x": 15,
      "y": 1,
      "z": -2,
      "name": "Rock_Stone_Cobble"
    },
    {
      "x": 15,
      "y": 4,
      "z": -2,
      "name": "Wood_Beech_Branch_Corner",
      "support": 15,
      "rotation": 1
    },
    {
      "x": 15,
      "y": 5,
      "z": -2,
      "name": "Wood_Softwood_Roof",
      "rotation": 1
    },
    {
      "x": 15,
      "y": 1,
      "z": -1,
      "name": "Rock_Stone_Cobble"
    },
    {
      "x": 15,
      "y": 5,
      "z": -1,
      "name": "Wood_Softwood_Roof_Hollow",
      "rotation": 1
    }
  ]
}